Workbook

Sheet All Products
I1: Material Cost | L1: Material Cost itself more than Sales Price | O1: Labour Cost itself more than Sales Price
L2: Material Cost itself more than 60% of Sales Price | O2: Labour Cost itself more than 60% of Sales Price
A3: Product_Code | B3: Customer | C3: Product_Name | D3: UoM | E3: Pack Size (UoM) | F3: Sales Price Winter 24 | G3: Sales Price Summer 26 | H3: Status | I3: RM-FOOD | J3: RM-PACKING | K3: % | L3: Labour cost Food Processing | M3: Labour cost Packing | N3: % | O3: Chemical Cost | P3: Total Cost | Q3: Winter Cash Margin | R3: Margin | S3: Avg Monthly sales qty | T3: Avg Monthly sales Value (Summer) | U3: Margin Summer price | V3: Margin Winter price | W3: Change | X3: Comment
A4: 1145CS | B4: Reynolds | C4: PREP CARROTS JULIENNE 1KG | D4: KG | E4: =VLOOKUP(A4,BOM!A:E,5,0) -> 1 | F4: 1.67 | G4: 1.72 | H4: Active | I4: =SUMIFS(BOM!Q:Q,BOM!A:A,'All Products'!A4,BOM!I:I,'All Products'!I$3) -> 0.5044471 | J4: =SUMIFS(BOM!Q:Q,BOM!A:A,'All Products'!A4,BOM!I:I,'All Products'!J$3)+0.03 -> 0.39 | K4: =(I4+J4)/G4 -> 0.52002738 | L4: =SUMIF(BOM!A:A,'All Products'!A4,BOM!S:S) -> 0.30645053 | M4: =SUMIF(BOM!A:A,'All Products'!A4,BOM!V:V) -> 0.186175 | N4: =(L4+M4)/G4 -> 0.28641019 | O4: 0 | P4: =I4+J4+M4+L4+O4 -> 1.3870726 | Q4: =G4-P4 -> 0.33292737 | R4: =IFERROR((G4-P4)/G4,0) -> 0.19356242 | S4: 5639.2 | T4: =S4*F4 -> 9417.464 | U4: =IFERROR(S4*Q4,0) -> 1877.444 | V4: =(G4-P4)*S4 -> 1877.444 | W4: =V4-U4 -> 0 | Y4: =(G4-I4)/G4 -> 0.7067168 | AF4: 2180CS
A5: 1726CS | B5: Reynolds | C5: GINGER DICED 1 X 200G | D5: KG | E5: =VLOOKUP(A5,BOM!A:E,5,0) -> 0.2 | F5: 1.37 | G5: 1.5 | H5: Active | I5: =SUMIFS(BOM!Q:Q,BOM!A:A,'All Products'!A5,BOM!I:I,'All Products'!I$3) -> 0.47625962 | J5: =SUMIFS(BOM!Q:Q,BOM!A:A,'All Products'!A5,BOM!I:I,'All Products'!J$3)+0.03 -> 0.145 | K5: =(I5+J5)/G5 -> 0.41417308 | L5: =SUMIF(BOM!A:A,'All Products'!A5,BOM!S:S) -> 0.050775 | M5: =SUMIF(BOM!A:A,'All Products'!A5,BOM!V:V) -> 0.23695 | N5: =(L5+M5)/G5 -> 0.19181667 | O5: 0 | P5: =I5+J5+M5+L5+O5 -> 0.90898462 | Q5: =G5-P5 -> 0.59101538 | R5: =IFERROR((G5-P5)/G5,0) -> 0.39401025 | S5: 0 | T5: =S5*F5 -> 0 | U5: =IFERROR(S5*Q5,0) -> 0 | V5: =(G5-P5)*S5 -> 0 | W5: =V5-U5 -> 0 | Y5: =(G5-I5)/G5 -> 0.68249359 | AC5: Above 70% Margin | AF5: Z141CS
A6: 1851CS | B6: Reynolds | C6: PREP FRUIT SALAD MIX 2KG | D6: KG | E6: =VLOOKUP(A6,BOM!A:E,5,0) -> 2.7 | F6: 9.58 | G6: 9.75 | H6: Active | I6: =SUMIFS(BOM!Q:Q,BOM!A:A,'All Products'!A6,BOM!I:I,'All Products'!I$3) -> 3.8284912 | J6: =SUMIFS(BOM!Q:Q,BOM!A:A,'All Products'!A6,BOM!I:I,'All Products'!J$3)+0.03 -> 0.75 | K6: =(I6+J6)/G6 -> 0.46958884 | L6: =SUMIF(BOM!A:A,'All Products'!A6,BOM!S:S) -> 2.5716748 | M6: =SUMIF(BOM!A:A,'All Products'!A6,BOM!V:V) -> 0.8039375 | N6: =(L6+M6)/G6 -> 0.34621665 | O6: 0 | P6: =I6+J6+M6+L6+O6 -> 7.9541035 | Q6: =G6-P6 -> 1.7958965 | R6: =IFERROR((G6-P6)/G6,0) -> 0.18419451 | S6: 2114.8 | T6: =S6*F6 -> 20259.784 | U6: =IFERROR(S6*Q6,0) -> 3797.9619 | V6: =(G6-P6)*S6 -> 3797.9619 | W6: =V6-U6 -> 0 | Y6: =(G6-I6)/G6 -> 0.60733423 | AC6: Margin Less than 25% | AF6: Z140CS
A7: 1254CS | B7: Reynolds | C7: COLESLAW DRY MIX 1KG | D7: KG | E7: =VLOOKUP(A7,BOM!A:E,5,0) -> 1 | F7: 1.91 | G7: 1.95 | H7: Active | I7: =SUMIFS(BOM!Q:Q,BOM!A:A,'All Products'!A7,BOM!I:I,'All Products'!I$3) -> 0.45953517 | J7: =SUMIFS(BOM!Q:Q,BOM!A:A,'All Products'!A7,BOM!I:I,'All Products'!J$3)+0.03 -> 0.39 | K7: =(I7+J7)/G7 -> 0.43565906 | L7: =SUMIF(BOM!A:A,'All Products'!A7,BOM!S:S) -> 0.28806692 | M7: =SUMIF(BOM!A:A,'All Products'!A7,BOM!V:V) -> 0.186175 | N7: =(L7+M7)/G7 -> 0.24320099 | O7: 0 | P7: =I7+J7+M7+L7+O7 -> 1.3237771 | Q7: =G7-P7 -> 0.62622291 | R7: =IFERROR((G7-P7)/G7,0) -> 0.32113995 | S7: 2204.8 | T7: =S7*F7 -> 4211.168 | U7: =IFERROR(S7*Q7,0) -> 1380.6963 | V7: =(G7-P7)*S7 -> 1380.6963 | W7: =V7-U7 -> 0 | Y7: =(G7-I7)/G7 -> 0.76434094 | AC7: In loss | AF7: Z139CS
A8: 1310CS | B8: Reynolds | C8: PREP ONION DICED 5mm 2.5KG | D8: KG | E8: =VLOOKUP(A8,BOM!A:E,5,0) -> 2.5 | F8: 6.33 | G8: 6.36 | H8: Active | I8: =SUMIFS(BOM!Q:Q,BOM!A:A,'All Products'!A8,BOM!I:I,'All Products'!I$3) -> 2.6479274 | J8: =SUMIFS(BOM!Q:Q,BOM!A:A,'All Products'!A8,BOM!I:I,'All Products'!J$3)+0.03 -> 0.4 | K8: =(I8+J8)/G8 -> 0.47923388 | L8: =SUMIF(BOM!A:A,'All Products'!A8,BOM!S:S) -> 0.5500625 | M8: =SUMIF(BOM!A:A,'All Products'!A8,BOM!V:V) -> 0.2961875 | N8: =(L8+M8)/G8 -> 0.13305818 | O8: 0 | P8: =I8+J8+M8+L8+O8 -> 3.8941774 | Q8: =G8-P8 -> 2.4658226 | R8: =IFERROR((G8-P8)/G8,0) -> 0.38770795 | S8: 2053.2 | T8: =S8*F8 -> 12996.756 | U8: =IFERROR(S8*Q8,0) -> 5062.8269 | V8: =(G8-P8)*S8 -> 5062.8269 | W8: =V8-U8 -> 0 | Y8: =(G8-I8)/G8 -> 0.58365921 | AF8: Z138CS
A9: 1255CS | B9: Reynolds | C9: PREP COLESLAW DRY MIX 2.5KG | D9: KG | E9: =VLOOKUP(A9,BOM!A:E,5,0) -> 2.5 | F9: 3.29 | G9: 3.37 | H9: Active | I9: =SUMIFS(BOM!Q:Q,BOM!A:A,'All Products'!A9,BOM!I:I,'All Products'!I$3) -> 1.1488379 | J9: =SUMIFS(BOM!Q:Q,BOM!A:A,'All Products'!A9,BOM!I:I,'All Products'!J$3)+0.03 -> 0.39 | K9: =(I9+J9)/G9 -> 0.45662846 | L9: =SUMIF(BOM!A:A,'All Products'!A9,BOM!S:S) -> 0.72016731 | M9: =SUMIF(BOM!A:A,'All Products'!A9,BOM!V:V) -> 0.2961875 | N9: =(L9+M9)/G9 -> 0.30158896 | O9: 0 | P9: =I9+J9+M9+L9+O9 -> 2.5551927 | Q9: =G9-P9 -> 0.81480727 | R9: =IFERROR((G9-P9)/G9,0) -> 0.24178257 | S9: 1401 | T9: =S9*F9 -> 4609.29 | U9: =IFERROR(S9*Q9,0) -> 1141.545 | V9: =(G9-P9)*S9 -> 1141.545 | W9: =V9-U9 -> 0 | Y9: =(G9-I9)/G9 -> 0.65909854 | AF9: Z353CS
A10: 103ACS | B10: Reynolds | C10: DICED RED PEPPER 4 X 750G | D10: KG | E10: =VLOOKUP(A10,BOM!A:E,5,0) -> 3 | F10: 19.57 | G10: 20.01 | H10: Active | I10: =SUMIFS(BOM!Q:Q,BOM!A:A,'All Products'!A10,BOM!I:I,'All Products'!I$3) -> 7.406725 | J10: =SUMIFS(BOM!Q:Q,BOM!A:A,'All Products'!A10,BOM!I:I,'All Products'!J$3)+0.03 -> 0.63 | K10: =(I10+J10)/G10 -> 0.40163543 | L10: =SUMIF(BOM!A:A,'All Products'!A10,BOM!S:S) -> 1.0470222 | M10: =SUMIF(BOM!A:A,'All Products'!A10,BOM!V:V) -> 0.592375 | N10: =(L10+M10)/G10 -> 0.081928897 | O10: 0 | P10: =I10+J10+M10+L10+O10 -> 9.6761222 | Q10: =G10-P10 -> 10.333878 | R10: =IFERROR((G10-P10)/G10,0) -> 0.51643567 | S10: 1733.6 | T10: =S10*F10 -> 33926.552 | U10: =IFERROR(S10*Q10,0) -> 17914.811 | V10: =(G10-P10)*S10 -> 17914.811 | W10: =V10-U10 -> 0 | Y10: =(G10-I10)/G10 -> 0.62984883 | AF10: Z352CS
A11: 785ACS | B11: Reynolds | C11: PICKLED RED CABBAGE DL 1x1.3KG | D11: KG | E11: =VLOOKUP(A11,BOM!A:E,5,0) -> 1.3 | F11: 2.52 | G11: 2.66 | H11: Active | I11: =SUMIFS(BOM!Q:Q,BOM!A:A,'All Products'!A11,BOM!I:I,'All Products'!I$3) -> 1.6191797 | J11: =SUMIFS(BOM!Q:Q,BOM!A:A,'All Products'!A11,BOM!I:I,'All Products'!J$3)+0.03 -> 0.41 | K11: =(I11+J11)/G11 -> 0.7628495 | L11: =SUMIF(BOM!A:A,'All Products'!A11,BOM!S:S) -> 0.30300815 | M11: =SUMIF(BOM!A:A,'All Products'!A11,BOM!V:V) -> 0.2183325 | N11: =(L11+M11)/G11 -> 0.19599272 | O11: 0 | P11: =I11+J11+M11+L11+O11 -> 2.5505203 | Q11: =G11-P11 -> 0.10947967 | R11: =IFERROR((G11-P11)/G11,0) -> 0.041157772 | S11: 1170.4 | T11: =S11*F11 -> 2949.408 | U11: =IFERROR(S11*Q11,0) -> 128.13501 | V11: =(G11-P11)*S11 -> 128.13501 | W11: =V11-U11 -> 0 | Y11: =(G11-I11)/G11 -> 0.39128583 | AF11: N019CS
A12: 4486CS | B12: Reynolds | C12: FRUIT CUP 6 X 200G | D12: KG | E12: =VLOOKUP(A12,BOM!A:E,5,0) -> 1.2 | F12: 12.4 | G12: 12.79 | H12: Active | I12: =SUMIFS(BOM!Q:Q,BOM!A:A,'All Products'!A12,BOM!I:I,'All Products'!I$3) -> 3.2927673 | J12: =SUMIFS(BOM!Q:Q,BOM!A:A,'All Products'!A12,BOM!I:I,'All Products'!J$3)+0.03 -> 1.85 | K12: =(I12+J12)/G12 -> 0.40209283 | L12: =SUMIF(BOM!A:A,'All Products'!A12,BOM!S:S) -> 1.0761707 | M12: =SUMIF(BOM!A:A,'All Products'!A12,BOM!V:V) -> 0.8124 | N12: =(L12+M12)/G12 -> 0.14765994 | O12: 0 | P12: =I12+J12+M12+L12+O12 -> 7.031338 | Q12: =G12-P12 -> 5.758662 | R12: =IFERROR((G12-P12)/G12,0) -> 0.45024723 | S12: 1867.6 | T12: =S12*F12 -> 23158.24 | U12: =IFERROR(S12*Q12,0) -> 10754.877 | V12: =(G12-P12)*S12 -> 10754.877 | W12: =V12-U12 -> 0 | Y12: =(G12-I12)/G12 -> 0.74255142 | AF12: N037CS
A13: 655ACS | B13: Reynolds | C13: RED ONION SLICED 3MM 4x1KG | D13: KG | E13: =VLOOKUP(A13,BOM!A:E,5,0) -> 4 | F13: 7.82 | G13: 7.43 | H13: Active | I13: =SUMIFS(BOM!Q:Q,BOM!A:A,'All Products'!A13,BOM!I:I,'All Products'!I$3) -> 4.9687155 | J13: =SUMIFS(BOM!Q:Q,BOM!A:A,'All Products'!A13,BOM!I:I,'All Products'!J$3)+0.03 -> 0.63 | K13: =(I13+J13)/G13 -> 0.75352833 | L13: =SUMIF(BOM!A:A,'All Products'!A13,BOM!S:S) -> 1.24568 | M13: =SUMIF(BOM!A:A,'All Products'!A13,BOM!V:V) -> 0.592375 | N13: =(L13+M13)/G13 -> 0.24738291 | O13: 0 | P13: =I13+J13+M13+L13+O13 -> 7.4367705 | Q13: =G13-P13 -> -0.006770495 | R13: =IFERROR((G13-P13)/G13,0) -> -0.00091123755 | S13: 982.8 | T13: =S13*F13 -> 7685.496 | U13: =IFERROR(S13*Q13,0) -> -6.6540425 | V13: =(G13-P13)*S13 -> -6.6540425 | W13: =V13-U13 -> 0 | Y13: =(G13-I13)/G13 -> 0.33126306
A14: 104ACS | B14: Reynolds | C14: 5MM SLICED LEEK 4 X 600G | D14: KG | E14: =VLOOKUP(A14,BOM!A:E,5,0) -> 2.4 | F14: 10.21 | G14: 10.44 | H14: Active | I14: =SUMIFS(BOM!Q:Q,BOM!A:A,'All Products'!A14,BOM!I:I,'All Products'!I$3) -> 3.0361446 | J14: =SUMIFS(BOM!Q:Q,BOM!A:A,'All Products'!A14,BOM!I:I,'All Products'!J$3)+0.03 -> 0.63 | K14: =(I14+J14)/G14 -> 0.35116327 | L14: =SUMIF(BOM!A:A,'All Products'!A14,BOM!S:S) -> 0.62081904 | M14: =SUMIF(BOM!A:A,'All Products'!A14,BOM!V:V) -> 0.592375 | N14: =(L14+M14)/G14 -> 0.11620633 | O14: 0 | P14: =I14+J14+M14+L14+O14 -> 4.8793386 | Q14: =G14-P14 -> 5.5606614 | R14: =IFERROR((G14-P14)/G14,0) -> 0.5326304 | S14: 1491.4 | T14: =S14*F14 -> 15227.194 | U14: =IFERROR(S14*Q14,0) -> 8293.1704 | V14: =(G14-P14)*S14 -> 8293.1704 | W14: =V14-U14 -> 0 | Y14: =(G14-I14)/G14 -> 0.70918155
A15: 1854CS | B15: Reynolds | C15: PREP ORANGE SEGMENTS 2KG | D15: KG | E15: =VLOOKUP(A15,BOM!A:E,5,0) -> 2.7 | F15: 10.47 | G15: 10.82 | H15: Active | I15: =SUMIFS(BOM!Q:Q,BOM!A:A,'All Products'!A15,BOM!I:I,'All Products'!I$3) -> 3.4745 | J15: =SUMIFS(BOM!Q:Q,BOM!A:A,'All Products'!A15,BOM!I:I,'All Products'!J$3)+0.03 -> 0.75 | K15: =(I15+J15)/G15 -> 0.39043438 | L15: =SUMIF(BOM!A:A,'All Products'!A15,BOM!S:S) -> 3.3718361 | M15: =SUMIF(BOM!A:A,'All Products'!A15,BOM!V:V) -> 0.2708 | N15: =(L15+M15)/G15 -> 0.33665768 | O15: 0 | P15: =I15+J15+M15+L15+O15 -> 7.8671361 | Q15: =G15-P15 -> 2.9528639 | R15: =IFERROR((G15-P15)/G15,0) -> 0.27290794 | S15: 989.6 | T15: =S15*F15 -> 10361.112 | U15: =IFERROR(S15*Q15,0) -> 2922.1541 | V15: =(G15-P15)*S15 -> 2922.1541 | W15: =V15-U15 -> 0 | Y15: =(G15-I15)/G15 -> 0.6788817
A16: 1522CS | B16: Reynolds | C16: STIRFRY MIX WITH KALE 6 X 500G | D16: KG | E16: =VLOOKUP(A16,BOM!A:E,5,0) -> 3 | F16: 20.46 | G16: 21.06 | H16: Active | I16: =SUMIFS(BOM!Q:Q,BOM!A:A,'All Products'!A16,BOM!I:I,'All Products'!I$3) -> 2.5344022 | J16: =SUMIFS(BOM!Q:Q,BOM!A:A,'All Products'!A16,BOM!I:I,'All Products'!J$3)+0.03 -> 0.79 | K16: =(I16+J16)/G16 -> 0.15785385 | L16: =SUMIF(BOM!A:A,'All Products'!A16,BOM!S:S) -> 1.1874686 | M16: =SUMIF(BOM!A:A,'All Products'!A16,BOM!V:V) -> 0.8124 | N16: =(L16+M16)/G16 -> 0.094960523 | O16: 0 | P16: =I16+J16+M16+L16+O16 -> 5.3242708 | Q16: =G16-P16 -> 15.735729 | R16: =IFERROR((G16-P16)/G16,0) -> 0.74718562 | S16: 0 | T16: =S16*F16 -> 0 | U16: =IFERROR(S16*Q16,0) -> 0 | V16: =(G16-P16)*S16 -> 0 | W16: =V16-U16 -> 0 | Y16: =(G16-I16)/G16 -> 0.87965802
A17: 789ACS | B17: Reynolds | C17: STIR FRY VEG DL 1x1.5KG | D17: KG | E17: =VLOOKUP(A17,BOM!A:E,5,0) -> 1.5 | F17: 6.84 | G17: 6.98 | H17: Active | I17: =SUMIFS(BOM!Q:Q,BOM!A:A,'All Products'!A17,BOM!I:I,'All Products'!I$3) -> #N/A | J17: =SUMIFS(BOM!Q:Q,BOM!A:A,'All Products'!A17,BOM!I:I,'All Products'!J$3)+0.03 -> 0.4 | K17: =(I17+J17)/G17 -> #N/A | L17: =SUMIF(BOM!A:A,'All Products'!A17,BOM!S:S) -> 0.86058562 | M17: =SUMIF(BOM!A:A,'All Products'!A17,BOM!V:V) -> 0.2183325 | N17: =(L17+M17)/G17 -> 0.1545728 | O17: 0 | P17: =I17+J17+M17+L17+O17 -> #N/A | Q17: =G17-P17 -> #N/A | R17: =IFERROR((G17-P17)/G17,0) -> 0 | S17: 105.4 | T17: =S17*F17 -> 720.936 | U17: =IFERROR(S17*Q17,0) -> 0 | V17: =(G17-P17)*S17 -> #N/A | W17: =V17-U17 -> #N/A | Y17: =(G17-I17)/G17 -> #N/A
A18: 1185CS | B18: Reynolds | C18: PREP CABBAGE RED SHRED 2.5KG | D18: KG | E18: =VLOOKUP(A18,BOM!A:E,5,0) -> 2.5 | F18: 3.87 | G18: 3.95 | H18: Active | I18: =SUMIFS(BOM!Q:Q,BOM!A:A,'All Products'!A18,BOM!I:I,'All Products'!I$3) -> 1.6636047 | J18: =SUMIFS(BOM!Q:Q,BOM!A:A,'All Products'!A18,BOM!I:I,'All Products'!J$3)+0.03 -> 0.4 | K18: =(I18+J18)/G18 -> 0.52243158 | L18: =SUMIF(BOM!A:A,'All Products'!A18,BOM!S:S) -> 0.64536354 | M18: =SUMIF(BOM!A:A,'All Products'!A18,BOM!V:V) -> 0.2961875 | N18: =(L18+M18)/G18 -> 0.23836735 | O18: 0 | P18: =I18+J18+M18+L18+O18 -> 3.0051558 | Q18: =G18-P18 -> 0.94484422 | R18: =IFERROR((G18-P18)/G18,0) -> 0.23920107 | S18: 1063.8 | T18: =S18*F18 -> 4116.906 | U18: =IFERROR(S18*Q18,0) -> 1005.1253 | V18: =(G18-P18)*S18 -> 1005.1253 | W18: =V18-U18 -> 0 | Y18: =(G18-I18)/G18 -> 0.57883424
A19: 1536CS | B19: Reynolds | C19: BUTTERNUTSQSH DICED 25MM 2.5KG | D19: KG | E19: =VLOOKUP(A19,BOM!A:E,5,0) -> 2.5 | F19: 7.83 | G19: 7.81 | H19: Active | I19: =SUMIFS(BOM!Q:Q,BOM!A:A,'All Products'!A19,BOM!I:I,'All Products'!I$3) -> 2.2569444 | J19: =SUMIFS(BOM!Q:Q,BOM!A:A,'All Products'!A19,BOM!I:I,'All Products'!J$3)+0.03 -> 0.4 | K19: =(I19+J19)/G19 -> 0.34019775 | L19: =SUMIF(BOM!A:A,'All Products'!A19,BOM!S:S) -> 2.47105 | M19: =SUMIF(BOM!A:A,'All Products'!A19,BOM!V:V) -> 0.2961875 | N19: =(L19+M19)/G19 -> 0.35431978 | O19: 0 | P19: =I19+J19+M19+L19+O19 -> 5.4241819 | Q19: =G19-P19 -> 2.3858181 | R19: =IFERROR((G19-P19)/G19,0) -> 0.30548247 | S19: 1086.8 | T19: =S19*F19 -> 8509.644 | U19: =IFERROR(S19*Q19,0) -> 2592.9071 | V19: =(G19-P19)*S19 -> 2592.9071 | W19: =V19-U19 -> 0 | Y19: =(G19-I19)/G19 -> 0.71101864
A20: 808ACS | B20: Reynolds | C20: COURGETTI 2 X 500G | D20: KG | E20: =VLOOKUP(A20,BOM!A:E,5,0) -> 1 | F20: 4.98 | G20: 5.07 | H20: In Active | I20: =SUMIFS(BOM!Q:Q,BOM!A:A,'All Products'!A20,BOM!I:I,'All Products'!I$3) -> 0 | J20: =SUMIFS(BOM!Q:Q,BOM!A:A,'All Products'!A20,BOM!I:I,'All Products'!J$3)+0.03 -> 0.49 | K20: =(I20+J20)/G20 -> 0.096646943 | L20: =SUMIF(BOM!A:A,'All Products'!A20,BOM!S:S) -> 0.03385 | M20: =SUMIF(BOM!A:A,'All Products'!A20,BOM!V:V) -> 0.355425 | N20: =(L20+M20)/G20 -> 0.076780079 | O20: 0 | P20: =I20+J20+M20+L20+O20 -> 0.879275 | Q20: =G20-P20 -> 4.190725 | R20: =IFERROR((G20-P20)/G20,0) -> 0.82657298 | Y20: =(G20-I20)/G20 -> 1
A21: 1480CS | B21: Reynolds | C21: PREP ROOT VEG MIX CHNKY 2.5KG | D21: KG | E21: =VLOOKUP(A21,BOM!A:E,5,0) -> 2.5 | F21: 6.19 | G21: 6.24 | H21: Active | I21: =SUMIFS(BOM!Q:Q,BOM!A:A,'All Products'!A21,BOM!I:I,'All Products'!I$3) -> 2.3774492 | J21: =SUMIFS(BOM!Q:Q,BOM!A:A,'All Products'!A21,BOM!I:I,'All Products'!J$3)+0.03 -> 0.4 | K21: =(I21+J21)/G21 -> 0.44510404 | L21: =SUMIF(BOM!A:A,'All Products'!A21,BOM!S:S) -> 1.5760524 | M21: =SUMIF(BOM!A:A,'All Products'!A21,BOM!V:V) -> 0.2961875 | N21: =(L21+M21)/G21 -> 0.30003844 | O21: 0 | P21: =I21+J21+M21+L21+O21 -> 4.6496891 | Q21: =G21-P21 -> 1.5903109 | R21: =IFERROR((G21-P21)/G21,0) -> 0.25485752 | S21: 418.6 | T21: =S21*G21 -> 2612.064 | U21: =IFERROR(S21*Q21,0) -> 665.70416 | V21: =(G21-P21)*S21 -> 665.70416 | W21: =V21-U21 -> 0 | Y21: =(G21-I21)/G21 -> 0.61899853
A22: 1303CS | B22: Reynolds | C22: PREP WHITE ONION SLICED 2.5KG | D22: KG | E22: =VLOOKUP(A22,BOM!A:E,5,0) -> 2.5 | F22: 5.94 | G22: 5.98 | H22: Active | I22: =SUMIFS(BOM!Q:Q,BOM!A:A,'All Products'!A22,BOM!I:I,'All Products'!I$3) -> 2.4369562 | J22: =SUMIFS(BOM!Q:Q,BOM!A:A,'All Products'!A22,BOM!I:I,'All Products'!J$3)+0.03 -> 0.4 | K22: =(I22+J22)/G22 -> 0.47440738 | L22: =SUMIF(BOM!A:A,'All Products'!A22,BOM!S:S) -> 0.6177625 | M22: =SUMIF(BOM!A:A,'All Products'!A22,BOM!V:V) -> 0.2961875 | N22: =(L22+M22)/G22 -> 0.15283445 | O22: 0 | P22: =I22+J22+M22+L22+O22 -> 3.7509062 | Q22: =G22-P22 -> 2.2290938 | R22: =IFERROR((G22-P22)/G22,0) -> 0.37275817 | S22: 751.2 | T22: =S22*G22 -> 4492.176 | U22: =IFERROR(S22*Q22,0) -> 1674.4953 | V22: =(G22-P22)*S22 -> 1674.4953 | W22: =V22-U22 -> 0 | Y22: =(G22-I22)/G22 -> 0.59248225
A23: 1180CS | B23: Reynolds | C23: RED CABBAGE N CARROT SLAW 2X1K | D23: KG | E23: =VLOOKUP(A23,BOM!A:E,5,0) -> 2 | F23: 2.17 | G23: 2.33 | H23: Active | I23: =SUMIFS(BOM!Q:Q,BOM!A:A,'All Products'!A23,BOM!I:I,'All Products'!I$3) -> 1.0693587 | J23: =SUMIFS(BOM!Q:Q,BOM!A:A,'All Products'!A23,BOM!I:I,'All Products'!J$3)+0.03 -> 0.47 | K23: =(I23+J23)/G23 -> 0.66066899 | L23: =SUMIF(BOM!A:A,'All Products'!A23,BOM!S:S) -> 0.60690892 | M23: =SUMIF(BOM!A:A,'All Products'!A23,BOM!V:V) -> 0.2961875 | N23: =(L23+M23)/G23 -> 0.38759503 | O23: 0 | P23: =I23+J23+M23+L23+O23 -> 2.4424552 | Q23: =G23-P23 -> -0.11245517 | R23: =IFERROR((G23-P23)/G23,0) -> -0.04826402 | S23: 613.4 | T23: =S23*G23 -> 1429.222 | U23: =IFERROR(S23*Q23,0) -> -68.979999 | V23: =(G23-P23)*S23 -> -68.979999 | W23: =V23-U23 -> 0 | Y23: =(G23-I23)/G23 -> 0.54104775
A24: 765ACS | B24: Reynolds | C24: COLESLAW MIX 8x500G | D24: KG | E24: =VLOOKUP(A24,BOM!A:E,5,0) -> 4 | F24: 10.32 | G24: 10.6 | H24: Active | I24: =SUMIFS(BOM!Q:Q,BOM!A:A,'All Products'!A24,BOM!I:I,'All Products'!I$3) -> 2.0203659 | J24: =SUMIFS(BOM!Q:Q,BOM!A:A,'All Products'!A24,BOM!I:I,'All Products'!J$3)+0.03 -> 0.95 | K24: =(I24+J24)/G24 -> 0.2802232 | L24: =SUMIF(BOM!A:A,'All Products'!A24,BOM!S:S) -> 1.1291919 | M24: =SUMIF(BOM!A:A,'All Products'!A24,BOM!V:V) -> 0.77855 | N24: =(L24+M24)/G24 -> 0.17997565 | O24: 0 | P24: =I24+J24+M24+L24+O24 -> 4.8781078 | Q24: =G24-P24 -> 5.7218922 | R24: =IFERROR((G24-P24)/G24,0) -> 0.53980115 | S24: 576.2 | T24: =S24*G24 -> 6107.72 | U24: =IFERROR(S24*Q24,0) -> 3296.9543 | V24: =(G24-P24)*S24 -> 3296.9543 | W24: =V24-U24 -> 0 | Y24: =(G24-I24)/G24 -> 0.80939945
A25: 1855CS | B25: Reynolds | C25: PREP GRAPEFRUIT PINK SEG 2KG | D25: KG | E25: =VLOOKUP(A25,BOM!A:E,5,0) -> 2.7 | F25: 15 | G25: 15.38 | H25: Active | I25: =SUMIFS(BOM!Q:Q,BOM!A:A,'All Products'!A25,BOM!I:I,'All Products'!I$3) -> 4.6594846 | J25: =SUMIFS(BOM!Q:Q,BOM!A:A,'All Products'!A25,BOM!I:I,'All Products'!J$3)+0.03 -> 0.75 | K25: =(I25+J25)/G25 -> 0.35172202 | L25: =SUMIF(BOM!A:A,'All Products'!A25,BOM!S:S) -> 3.2022264 | M25: =SUMIF(BOM!A:A,'All Products'!A25,BOM!V:V) -> 0.2708 | N25: =(L25+M25)/G25 -> 0.22581446 | O25: 0 | P25: =I25+J25+M25+L25+O25 -> 8.882511 | Q25: =G25-P25 -> 6.497489 | R25: =IFERROR((G25-P25)/G25,0) -> 0.42246352 | S25: 518 | T25: =S25*G25 -> 7966.84 | U25: =IFERROR(S25*Q25,0) -> 3365.6993 | V25: =(G25-P25)*S25 -> 3365.6993 | W25: =V25-U25 -> 0 | Y25: =(G25-I25)/G25 -> 0.69704261
A26: 1822CS | B26: Reynolds | C26: LEMON WEDGES X 2KG | D26: KG | E26: =VLOOKUP(A26,BOM!A:E,5,0) -> 2 | F26: 6.32 | G26: 6.78 | H26: Active | I26: =SUMIFS(BOM!Q:Q,BOM!A:A,'All Products'!A26,BOM!I:I,'All Products'!I$3) -> 2.2985455 | J26: =SUMIFS(BOM!Q:Q,BOM!A:A,'All Products'!A26,BOM!I:I,'All Products'!J$3)+0.03 -> 0.75 | K26: =(I26+J26)/G26 -> 0.44963797 | L26: =SUMIF(BOM!A:A,'All Products'!A26,BOM!S:S) -> 2.3976211 | M26: =SUMIF(BOM!A:A,'All Products'!A26,BOM!V:V) -> 0.2708 | N26: =(L26+M26)/G26 -> 0.39357243 | O26: 0 | P26: =I26+J26+M26+L26+O26 -> 5.7169666 | Q26: =G26-P26 -> 1.0630334 | R26: =IFERROR((G26-P26)/G26,0) -> 0.15678959 | S26: 171.8 | T26: =S26*G26 -> 1164.804 | U26: =IFERROR(S26*Q26,0) -> 182.62914 | V26: =(G26-P26)*S26 -> 182.62914 | W26: =V26-U26 -> 0 | Y26: =(G26-I26)/G26 -> 0.6609815
A27: 719ACS | B27: Reynolds | C27: BENUGO PREP PINEAPPLE CUBE 2KG | D27: KG | E27: =VLOOKUP(A27,BOM!A:E,5,0) -> 2.7 | F27: 10.06 | G27: 10.26 | H27: Active | I27: =SUMIFS(BOM!Q:Q,BOM!A:A,'All Products'!A27,BOM!I:I,'All Products'!I$3) -> 3.5441 | J27: =SUMIFS(BOM!Q:Q,BOM!A:A,'All Products'!A27,BOM!I:I,'All Products'!J$3)+0.03 -> 0.75 | K27: =(I27+J27)/G27 -> 0.41852827 | L27: =SUMIF(BOM!A:A,'All Products'!A27,BOM!S:S) -> 1.0980321 | M27: =SUMIF(BOM!A:A,'All Products'!A27,BOM!V:V) -> 0.2708 | N27: =(L27+M27)/G27 -> 0.13341443 | O27: 0 | P27: =I27+J27+M27+L27+O27 -> 5.6629321 | Q27: =G27-P27 -> 4.5970679 | R27: =IFERROR((G27-P27)/G27,0) -> 0.4480573 | S27: 143.8 | T27: =S27*G27 -> 1475.388 | U27: =IFERROR(S27*Q27,0) -> 661.05837 | V27: =(G27-P27)*S27 -> 661.05837 | W27: =V27-U27 -> 0 | Y27: =(G27-I27)/G27 -> 0.65457115
A28: 1174CS | B28: Reynolds | C28: PREP CARROTS GRATED 4 X 1KG | D28: KG | E28: =VLOOKUP(A28,BOM!A:E,5,0) -> 4 | F28: 6.36 | G28: 6.56 | H28: Active | I28: =SUMIFS(BOM!Q:Q,BOM!A:A,'All Products'!A28,BOM!I:I,'All Products'!I$3) -> 2.0177884 | J28: =SUMIFS(BOM!Q:Q,BOM!A:A,'All Products'!A28,BOM!I:I,'All Products'!J$3)+0.03 -> 0.63 | K28: =(I28+J28)/G28 -> 0.40362628 | L28: =SUMIF(BOM!A:A,'All Products'!A28,BOM!S:S) -> 1.2258021 | M28: =SUMIF(BOM!A:A,'All Products'!A28,BOM!V:V) -> 0.592375 | N28: =(L28+M28)/G28 -> 0.27716115 | O28: 0 | P28: =I28+J28+M28+L28+O28 -> 4.4659655 | Q28: =G28-P28 -> 2.0940345 | R28: =IFERROR((G28-P28)/G28,0) -> 0.31921257 | S28: 325.8 | T28: =S28*G28 -> 2137.248 | U28: =IFERROR(S28*Q28,0) -> 682.23643 | V28: =(G28-P28)*S28 -> 682.23643 | W28: =V28-U28 -> 0 | Y28: =(G28-I28)/G28 -> 0.69241031
A29: 1852CS | B29: Reynolds | C29: PREP FRUIT SALAD TROP 2KG | D29: KG | E29: =VLOOKUP(A29,BOM!A:E,5,0) -> 2.7 | F29: 11.75 | G29: 12.09 | H29: Active | I29: =SUMIFS(BOM!Q:Q,BOM!A:A,'All Products'!A29,BOM!I:I,'All Products'!I$3) -> 5.530457 | J29: =SUMIFS(BOM!Q:Q,BOM!A:A,'All Products'!A29,BOM!I:I,'All Products'!J$3)+0.03 -> 0.75 | K29: =(I29+J29)/G29 -> 0.51947535 | L29: =SUMIF(BOM!A:A,'All Products'!A29,BOM!S:S) -> 3.0905482 | M29: =SUMIF(BOM!A:A,'All Products'!A29,BOM!V:V) -> 0.6093 | N29: =(L29+M29)/G29 -> 0.30602549 | O29: 0 | P29: =I29+J29+M29+L29+O29 -> 9.9803052 | Q29: =G29-P29 -> 2.1096948 | R29: =IFERROR((G29-P29)/G29,0) -> 0.17449916 | S29: 291.2 | T29: =S29*G29 -> 3520.608 | U29: =IFERROR(S29*Q29,0) -> 614.34313 | V29: =(G29-P29)*S29 -> 614.34313 | W29: =V29-U29 -> 0 | Y29: =(G29-I29)/G29 -> 0.54255939
A30: 502ACS | B30: Reynolds | C30: NHS PREP STEW PACK 2.5KG | D30: KG | E30: =VLOOKUP(A30,BOM!A:E,5,0) -> 2.5 | F30: 8.09 | G30: 8.42 | H30: Active | I30: =SUMIFS(BOM!Q:Q,BOM!A:A,'All Products'!A30,BOM!I:I,'All Products'!I$3) -> 2.1436438 | J30: =SUMIFS(BOM!Q:Q,BOM!A:A,'All Products'!A30,BOM!I:I,'All Products'!J$3)+0.03 -> 0.4 | K30: =(I30+J30)/G30 -> 0.30209547 | L30: =SUMIF(BOM!A:A,'All Products'!A30,BOM!S:S) -> 2.8236506 | M30: =SUMIF(BOM!A:A,'All Products'!A30,BOM!V:V) -> 0.2961875 | N30: =(L30+M30)/G30 -> 0.37052709 | O30: 0 | P30: =I30+J30+M30+L30+O30 -> 5.6634819 | Q30: =G30-P30 -> 2.7565181 | R30: =IFERROR((G30-P30)/G30,0) -> 0.32737744 | S30: 282.6 | T30: =S30*G30 -> 2379.492 | U30: =IFERROR(S30*Q30,0) -> 778.99201 | V30: =(G30-P30)*S30 -> 778.99201 | W30: =V30-U30 -> 0 | Y30: =(G30-I30)/G30 -> 0.74541047
A31: 1298CS | B31: Reynolds | C31: PREP ONION RED SLICED 2.5KG | D31: KG | E31: =VLOOKUP(A31,BOM!A:E,5,0) -> 2.5 | F31: 6.48 | G31: 6.01 | H31: Active | I31: =SUMIFS(BOM!Q:Q,BOM!A:A,'All Products'!A31,BOM!I:I,'All Products'!I$3) -> 3.1877446 | J31: =SUMIFS(BOM!Q:Q,BOM!A:A,'All Products'!A31,BOM!I:I,'All Products'!J$3)+0.03 -> 0.4 | K31: =(I31+J31)/G31 -> 0.5969625 | L31: =SUMIF(BOM!A:A,'All Products'!A31,BOM!S:S) -> 0.6177625 | M31: =SUMIF(BOM!A:A,'All Products'!A31,BOM!V:V) -> 0.2961875 | N31: =(L31+M31)/G31 -> 0.15207155 | O31: 0 | P31: =I31+J31+M31+L31+O31 -> 4.5016946 | Q31: =G31-P31 -> 1.5083054 | R31: =IFERROR((G31-P31)/G31,0) -> 0.25096595 | S31: 315.4 | T31: =S31*G31 -> 1895.554 | U31: =IFERROR(S31*Q31,0) -> 475.71951 | V31: =(G31-P31)*S31 -> 475.71951 | W31: =V31-U31 -> 0 | Y31: =(G31-I31)/G31 -> 0.46959324
A32: 484ACS | B32: Reynolds | C32: NHS DICED ONION 15MM 2.5KG | D32: KG | E32: =VLOOKUP(A32,BOM!A:E,5,0) -> 2.5 | F32: 7.01 | G32: 7.09 | H32: Active | I32: =SUMIFS(BOM!Q:Q,BOM!A:A,'All Products'!A32,BOM!I:I,'All Products'!I$3) -> 2.4336637 | J32: =SUMIFS(BOM!Q:Q,BOM!A:A,'All Products'!A32,BOM!I:I,'All Products'!J$3)+0.03 -> 0.4 | K32: =(I32+J32)/G32 -> 0.39967048 | L32: =SUMIF(BOM!A:A,'All Products'!A32,BOM!S:S) -> 0.423125 | M32: =SUMIF(BOM!A:A,'All Products'!A32,BOM!V:V) -> 0.2961875 | N32: =(L32+M32)/G32 -> 0.10145451 | O32: 0 | P32: =I32+J32+M32+L32+O32 -> 3.5529762 | Q32: =G32-P32 -> 3.5370238 | R32: =IFERROR((G32-P32)/G32,0) -> 0.49887501 | S32: 280.2 | T32: =S32*G32 -> 1986.618 | U32: =IFERROR(S32*Q32,0) -> 991.07407 | V32: =(G32-P32)*S32 -> 991.07407 | W32: =V32-U32 -> 0 | Y32: =(G32-I32)/G32 -> 0.65674701
... A41: 1311CS | B41: Reynolds | C41: PREP DICED ONION 5MM 1KG | D41: KG | E41: =VLOOKUP(A41,BOM!A:E,5,0) -> 1 | F41: 3.59 | G41: 3.62 | H41: Active | I41: =SUMIFS(BOM!Q:Q,BOM!A:A,'All Products'!A41,BOM!I:I,'All Products'!I$3) -> 1.059171 | J41: =SUMIFS(BOM!Q:Q,BOM!A:A,'All Products'!A41,BOM!I:I,'All Products'!J$3)+0.03 -> 0.4 | K41: =(I41+J41)/G41 -> 0.40308591 | L41: =SUMIF(BOM!A:A,'All Products'!A41,BOM!S:S) -> 0.220025 | M41: =SUMIF(BOM!A:A,'All Products'!A41,BOM!V:V) -> 0.2183325 | N41: =(L41+M41)/G41 -> 0.12109323 | O41: 0 | P41: =I41+J41+M41+L41+O41 -> 1.8975285 | Q41: =G41-P41 -> 1.7224715 | R41: =IFERROR((G41-P41)/G41,0) -> 0.47582086 | S41: 154.2 | T41: =S41*G41 -> 558.204 | U41: =IFERROR(S41*Q41,0) -> 265.60511 | V41: =(G41-P41)*S41 -> 265.60511 | W41: =V41-U41 -> 0 | Y41: =(G41-I41)/G41 -> 0.70741133
A42: 1193CS | B42: Reynolds | C42: PREP CABBAGE WHITE SHRED 2.5KG | D42: KG | E42: =VLOOKUP(A42,BOM!A:E,5,0) -> 2.5 | F42: 3.53 | G42: 3.6 | H42: Active | I42: =SUMIFS(BOM!Q:Q,BOM!A:A,'All Products'!A42,BOM!I:I,'All Products'!I$3) -> 1.4568326 | J42: =SUMIFS(BOM!Q:Q,BOM!A:A,'All Products'!A42,BOM!I:I,'All Products'!J$3)+0.03 -> 0.4 | K42: =(I42+J42)/G42 -> 0.51578685 | L42: =SUMIF(BOM!A:A,'All Products'!A42,BOM!S:S) -> 0.70047058 | M42: =SUMIF(BOM!A:A,'All Products'!A42,BOM!V:V) -> 0.2961875 | N42: =(L42+M42)/G42 -> 0.27684947 | O42: 0 | P42: =I42+J42+M42+L42+O42 -> 2.8534907 | Q42: =G42-P42 -> 0.74650927 | R42: =IFERROR((G42-P42)/G42,0) -> 0.20736369 | S42: 286.4 | T42: =S42*G42 -> 1031.04 | U42: =IFERROR(S42*Q42,0) -> 213.80026 | V42: =(G42-P42)*S42 -> 213.80026 | W42: =V42-U42 -> 0 | Y42: =(G42-I42)/G42 -> 0.59532427 | AA42: 2.86 | AB42: 2.44
A43: 487ACS | B43: Reynolds | C43: NHS PREP POTS QUARTERED 5KG | D43: KG | E43: =VLOOKUP(A43,BOM!A:E,5,0) -> 5 | F43: 9.26 | G43: 8.18 | H43: Active | I43: =SUMIFS(BOM!Q:Q,BOM!A:A,'All Products'!A43,BOM!I:I,'All Products'!I$3) -> 2.1049715 | J43: =SUMIFS(BOM!Q:Q,BOM!A:A,'All Products'!A43,BOM!I:I,'All Products'!J$3)+0.03 -> 0.4 | K43: =(I43+J43)/G43 -> 0.30623124 | L43: =SUMIF(BOM!A:A,'All Products'!A43,BOM!S:S) -> 4.518165 | M43: =SUMIF(BOM!A:A,'All Products'!A43,BOM!V:V) -> 0.4011225 | N43: =(L43+M43)/G43 -> 0.60137989 | O43: 0 | P43: =I43+J43+M43+L43+O43 -> 7.424259 | Q43: =G43-P43 -> 0.755741 | R43: =IFERROR((G43-P43)/G43,0) -> 0.092388876 | S43: 121.4 | T43: =S43*G43 -> 993.052 | U43: =IFERROR(S43*Q43,0) -> 91.746958 | V43: =(G43-P43)*S43 -> 91.746958 | W43: =V43-U43 -> 0 | Y43: =(G43-I43)/G43 -> 0.74266852
A44: 1335CS | B44: Reynolds | C44: PREP SWEET POTS WHOLE 2.5KG | D44: KG | E44: =VLOOKUP(A44,BOM!A:E,5,0) -> 2.5 | F44: 6.99 | G44: 6.41 | H44: Active | I44: =SUMIFS(BOM!Q:Q,BOM!A:A,'All Products'!A44,BOM!I:I,'All Products'!I$3) -> 2.6748397 | J44: =SUMIFS(BOM!Q:Q,BOM!A:A,'All Products'!A44,BOM!I:I,'All Products'!J$3)+0.03 -> 0.4 | K44: =(I44+J44)/G44 -> 0.47969419 | L44: =SUMIF(BOM!A:A,'All Products'!A44,BOM!S:S) -> 1.0250871 | M44: =SUMIF(BOM!A:A,'All Products'!A44,BOM!V:V) -> 0.2961875 | N44: =(L44+M44)/G44 -> 0.20612709 | O44: 0 | P44: =I44+J44+M44+L44+O44 -> 4.3961144 | Q44: =G44-P44 -> 2.0138856 | R44: =IFERROR((G44-P44)/G44,0) -> 0.31417872 | S44: 23.8 | T44: =S44*G44 -> 152.558 | U44: =IFERROR(S44*Q44,0) -> 47.930478 | V44: =(G44-P44)*S44 -> 47.930478 | W44: =V44-U44 -> 0 | Y44: =(G44-I44)/G44 -> 0.58270831
A45: 280ACS | B45: Reynolds | C45: NHS PREP SLICED CARROT 2.5KG | D45: KG | E45: =VLOOKUP(A45,BOM!A:E,5,0) -> 2.5 | F45: 4.04 | G45: 4.37 | H45: Active | I45: =SUMIFS(BOM!Q:Q,BOM!A:A,'All Products'!A45,BOM!I:I,'All Products'!I$3) -> 1.3221807 | J45: =SUMIFS(BOM!Q:Q,BOM!A:A,'All Products'!A45,BOM!I:I,'All Products'!J$3)+0.03 -> 0.4 | K45: =(I45+J45)/G45 -> 0.39409168 | L45: =SUMIF(BOM!A:A,'All Products'!A45,BOM!S:S) -> 1.4480148 | M45: =SUMIF(BOM!A:A,'All Products'!A45,BOM!V:V) -> 0.2961875 | N45: =(L45+M45)/G45 -> 0.39913096 | O45: 0 | P45: =I45+J45+M45+L45+O45 -> 3.466383 | Q45: =G45-P45 -> 0.90361703 | R45: =IFERROR((G45-P45)/G45,0) -> 0.20677735 | S45: 123.8 | T45: =S45*G45 -> 541.006 | U45: =IFERROR(S45*Q45,0) -> 111.86779 | V45: =(G45-P45)*S45 -> 111.86779 | W45: =V45-U45 -> 0 | Y45: =(G45-I45)/G45 -> 0.6974415
A46: 489ACS | B46: Reynolds | C46: NHS DICED BUTTERNUT 15MM 1KG | D46: KG | E46: =VLOOKUP(A46,BOM!A:E,5,0) -> 1 | F46: 2.33 | G46: 2.31 | H46: Active | I46: =SUMIFS(BOM!Q:Q,BOM!A:A,'All Products'!A46,BOM!I:I,'All Products'!I$3) -> 0.89652024 | J46: =SUMIFS(BOM!Q:Q,BOM!A:A,'All Products'!A46,BOM!I:I,'All Products'!J$3)+0.03 -> 0.4 | K46: =(I46+J46)/G46 -> 0.56126417 | L46: =SUMIF(BOM!A:A,'All Products'!A46,BOM!S:S) -> 0.57639525 | M46: =SUMIF(BOM!A:A,'All Products'!A46,BOM!V:V) -> 0.2183325 | N46: =(L46+M46)/G46 -> 0.34403799 | O46: 0 | P46: =I46+J46+M46+L46+O46 -> 2.091248 | Q46: =G46-P46 -> 0.21875201 | R46: =IFERROR((G46-P46)/G46,0) -> 0.094697838 | S46: 101.8 | T46: =S46*G46 -> 235.158 | U46: =IFERROR(S46*Q46,0) -> 22.268954 | V46: =(G46-P46)*S46 -> 22.268954 | W46: =V46-U46 -> 0 | Y46: =(G46-I46)/G46 -> 0.611896 | AA46: 553CEA COLESLAW MIX 1x500G
A47: 278ACS | B47: Reynolds | C47: NHS PREP DICED POTATO 20MM 5KG | D47: KG | E47: =VLOOKUP(A47,BOM!A:E,5,0) -> 5 | F47: 7.74 | G47: 7.28 | H47: Active | I47: =SUMIFS(BOM!Q:Q,BOM!A:A,'All Products'!A47,BOM!I:I,'All Products'!I$3) -> 4.6556129 | J47: =SUMIFS(BOM!Q:Q,BOM!A:A,'All Products'!A47,BOM!I:I,'All Products'!J$3)+0.03 -> 0.4 | K47: =(I47+J47)/G47 -> 0.69445232 | L47: =SUMIF(BOM!A:A,'All Products'!A47,BOM!S:S) -> 3.4814543 | M47: =SUMIF(BOM!A:A,'All Products'!A47,BOM!V:V) -> 0.4011225 | N47: =(L47+M47)/G47 -> 0.53332099 | O47: 0 | P47: =I47+J47+M47+L47+O47 -> 8.9381897 | Q47: =G47-P47 -> -1.6581897 | R47: =IFERROR((G47-P47)/G47,0) -> -0.22777331 | S47: 41 | T47: =S47*G47 -> 298.48 | U47: =IFERROR(S47*Q47,0) -> -67.985778 | V47: =(G47-P47)*S47 -> -67.985778 | W47: =V47-U47 -> 0 | Y47: =(G47-I47)/G47 -> 0.36049273 | AA47: N114CS COLESLAW MIX 1x500G
A48: 584ACS | B48: Reynolds | C48: PICKLED MOOLI 4 X 1.3KG | D48: KG | E48: =VLOOKUP(A48,BOM!A:E,5,0) -> 5.2 | F48: 17.24 | G48: 17.39 | H48: Active | I48: =SUMIFS(BOM!Q:Q,BOM!A:A,'All Products'!A48,BOM!I:I,'All Products'!I$3) -> 10.397029 | J48: =SUMIFS(BOM!Q:Q,BOM!A:A,'All Products'!A48,BOM!I:I,'All Products'!J$3)+0.03 -> 0.71 | K48: =(I48+J48)/G48 -> 0.63870205 | L48: =SUMIF(BOM!A:A,'All Products'!A48,BOM!S:S) -> 2.0633735 | M48: =SUMIF(BOM!A:A,'All Products'!A48,BOM!V:V) -> 0.822555 | N48: =(L48+M48)/G48 -> 0.16595333 | O48: 0 | P48: =I48+J48+M48+L48+O48 -> 13.992957 | Q48: =G48-P48 -> 3.3970429 | R48: =IFERROR((G48-P48)/G48,0) -> 0.19534462 | S48: 159.6 | T48: =S48*G48 -> 2775.444 | U48: =IFERROR(S48*Q48,0) -> 542.16805 | V48: =(G48-P48)*S48 -> 542.16805 | W48: =V48-U48 -> 0 | Y48: =(G48-I48)/G48 -> 0.40212602
...

Sheet BOM
A1: ITEM_CODE | B1: Customer | C1: ITEM_NAME | D1: UoM | E1: Pack Size (UoM) | F1: Material code | G1: Material Description | H1: Material/Process description | I1: Material/Category | J1: Output Qty % | K1: Output Qty | L1: Total Output qty | M1: Yield | N1: STD Material Per Qty | O1: UOM | P1: Price | Q1: M.Cost/pcs | R1: Labour Min/KG Out put | S1: Labour Cost (Processing)/Product | T1: Total Labour Hr/Product | U1: Labour Min/Packing | V1: Labour Cost (Packing)/Product | W1: Total Labour Hr/Packing | X1: Labour cost/product | Y1: Total Labour cost | Z1: Produced Qty | AA1: STD Consumption Qty | AB1: Total Material Cost | AC1: STD Labour Hrs | AD1: Total Labour Cost | AE1: Chemical Used | AF1: Chemical cost/kg input | AG1: Chemical cost/Product | AH1: Total Chemical Cost | AI1: Total Cost | AJ1: Sales Price | AK1: Sales Value | AL1: Low risk | AM1: High care | AN1: Labour Rate/Min | AO1: =20.31/60 -> 0.3385 | AP1: Time Factor | AQ1: total time/product | AR1: Group | AT1: Washed
A2: 1145CS | B2: Reynolds | C2: PREP CARROTS JULIENNE 1KG | D2: KG | E2: 1 | F2: =VLOOKUP(H2,'RM Used'!A:B,2,0) -> 032ACS | G2: =IFERROR(VLOOKUP(F2,'RM Cost'!A:B,2,0),"") -> RM - LRG PROCESSING CARROT X 1000KG | H2: Carrot - Julienne | I2: =VLOOKUP(F2,'RM Used'!B:D,3,0) -> RM-FOOD | J2: 1 | K2: =IF(I2="RM-FOOD",J2*E2,"") -> 1 | L2: =IFERROR(K2*Z2,0) -> 1 | M2: {=_xlfn.IFS(BOM!I2="RM-PACKING","100%",B2="Reynolds",VLOOKUP(H2,'Yield & Time'!A:V,22,0),BOM!B2="Dnata",VLOOKUP(BOM!H2,'Yield & Time'!A:M,13,0),B2="NK",VLOOKUP(H2,'Yield & Time'!A:X,24,0))} -> 0.7533 | N2: =IFERROR(IF(I2="RM-FOOD",(E2*J2)/M2,1),0) -> 1.3274924 | O2: =VLOOKUP(H2,'RM Used'!A:E,5,0) -> KG | P2: =VLOOKUP(H2,'RM Used'!A:F,6,0) -> 0.38 | Q2: =P2*N2 -> 0.5044471 | R2: =IFERROR(IF(B2="Reynolds",VLOOKUP(H2,'Yield & Time'!A:U,21,0),VLOOKUP(H2,'Yield & Time'!A:L,12,0)),0) -> 0.90531915 | S2: =R2*J2*E2*AO$1 -> 0.30645053 | T2: =(R2*Z2*J2*E2)/60 -> 0.015088652 | U2: =IF(A1=A2,0,VLOOKUP(A2,'Packing Time'!A:F,6,0)) -> 0.55 | V2: =U2*AO$1 -> 0.186175 | W2: =(U2*Z2)/60 -> 0.0091666667 | X2: =((R2*J2*E2)+U2)*AO$1*AP2 -> 0.54188809 | Y2: =X2*Z2 -> 0.54188809 | Z2: 1 | AA2: =Z2*N2 -> 1.3274924 | AB2: =AA2*P2 -> 0.5044471 | AC2: =(((R2*J2*E2)+U2)/60)*Z2*AP2 -> 0.026680851 | AD2: =AC2*60*AO$1 -> 0.54188809 | AE2: =VLOOKUP(H2,'Yield & Time'!A:R,18,0) -> CHLORINE | AF2: =IFERROR(VLOOKUP(AE2,'Chemical Cost'!A:D,4,0),0) -> 0.027756518 | AG2: =AF2*N2/3 -> 0.012282189 | AH2: =AF2*AA2/3 -> 0.012282189 | AI2: =IFERROR((Q2*Z2)+(Z2*X2)+AH2,0) -> 1.0586174 | AJ2: =IFERROR(VLOOKUP(A2,'All Products'!A:F,6,0),0) -> 1.67 | AK2: =AJ2*Z2*J2 -> 1.67 | AL2: 0.85 | AM2: 0.15 | AN2: #N/A | AP2: 1.1 | AQ2: =(((R2*J2*E2)+U2)/60)*AP2 -> 0.026680851 | AR2: =_xlfn.XLOOKUP(F2,'RM Cost'!A:A,'RM Cost'!S:S) -> 0 | AS2: =_xlfn.XLOOKUP(A2,[3]Sheet1!$B:$B,[3]Sheet1!$B:$B) -> 1145CS | AT2: =_xlfn.XLOOKUP(H2,'Yield & Time'!A:A,'Yield & Time'!O:O) -> Yes
A3: 1145CS | B3: Reynolds | C3: PREP CARROTS JULIENNE 1KG | D3: KG | E3: 1 | F3: =VLOOKUP(H3,'RM Used'!A:B,2,0) -> P0001 | G3: =IFERROR(VLOOKUP(F3,'RM Cost'!A:B,2,0),"") -> SOL 30EL # PPLUS 630x1000 BLUE -1 | H3: SOL 30EL # PPLUS 630x1000 BLUE -1 | I3: =VLOOKUP(F3,'RM Used'!B:D,3,0) -> RM-PACKING | J3: 1 | K3: =IF(I3="RM-FOOD",J3*E3,"") | L3: =IFERROR(K3*Z3,0) -> 0 | M3: {=_xlfn.IFS(BOM!I3="RM-PACKING","100%",B3="Reynolds",VLOOKUP(H3,'Yield & Time'!A:V,22,0),BOM!B3="Dnata",VLOOKUP(BOM!H3,'Yield & Time'!A:M,13,0),B3="NK",VLOOKUP(H3,'Yield & Time'!A:X,24,0))} -> 100% | N3: =IFERROR(IF(I3="RM-FOOD",(E3*J3)/M3,1),0) -> 1 | O3: =VLOOKUP(H3,'RM Used'!A:E,5,0) -> Count | P3: =VLOOKUP(H3,'RM Used'!A:F,6,0) -> 0.08 | Q3: =P3*N3 -> 0.08 | R3: =IFERROR(IF(B3="Reynolds",VLOOKUP(H3,'Yield & Time'!A:U,21,0),VLOOKUP(H3,'Yield & Time'!A:L,12,0)),0) -> 0 | S3: =R3*J3*E3*AO$1 -> 0 | T3: =(R3*Z3*J3*E3)/60 -> 0 | U3: =IF(A2=A3,0,VLOOKUP(A3,'Packing Time'!A:F,6,0)) -> 0 | V3: =U3*AO$1 -> 0 | W3: =(U3*Z3)/60 -> 0 | X3: =((R3*J3*E3)+U3)*AO$1*AP3 -> 0 | Y3: =X3*Z3 -> 0 | Z3: 1 | AA3: =Z3*N3 -> 1 | AB3: =AA3*P3 -> 0.08 | AC3: =(((R3*J3*E3)+U3)/60)*Z3*AP3 -> 0 | AD3: =AC3*60*AO$1 -> 0 | AF3: =IFERROR(VLOOKUP(AE3,'Chemical Cost'!A:D,4,0),0) -> 0 | AG3: =AF3*N3/3 -> 0 | AH3: =AF3*AA3/3 -> 0 | AI3: =IFERROR((Q3*Z3)+(Z3*X3)+AH3,0) -> 0.08 | AJ3: =IFERROR(VLOOKUP(A3,'All Products'!A:F,6,0),0) -> 1.67 | AL3: 0.85 | AM3: 0.15 | AN3: #N/A | AP3: 1.1 | AQ3: =(((R3*J3*E3)+U3)/60)*AP3 -> 0 | AR3: =_xlfn.XLOOKUP(F3,'RM Cost'!A:A,'RM Cost'!S:S) -> 0 | AS3: =_xlfn.XLOOKUP(A3,[3]Sheet1!$B:$B,[3]Sheet1!$B:$B) -> 1145CS | AT3: =_xlfn.XLOOKUP(H3,'Yield & Time'!A:A,'Yield & Time'!F:F) -> #N/A
A4: 1145CS | B4: Reynolds | C4: PREP CARROTS JULIENNE 1KG | D4: KG | E4: 1 | F4: =VLOOKUP(H4,'RM Used'!A:B,2,0) -> P0016 | G4: =IFERROR(VLOOKUP(F4,'RM Cost'!A:B,2,0),"") -> REY 40 30 BOX | H4: black box | I4: =VLOOKUP(F4,'RM Used'!B:D,3,0) -> RM-PACKING | J4: 1 | K4: =IF(I4="RM-FOOD",J4*E4,"") | L4: =IFERROR(K4*Z4,0) -> 0 | M4: {=_xlfn.IFS(BOM!I4="RM-PACKING","100%",B4="Reynolds",VLOOKUP(H4,'Yield & Time'!A:V,22,0),BOM!B4="Dnata",VLOOKUP(BOM!H4,'Yield & Time'!A:M,13,0),B4="NK",VLOOKUP(H4,'Yield & Time'!A:X,24,0))} -> 100% | N4: =IFERROR(IF(I4="RM-FOOD",(E4*J4)/M4,1),0) -> 1 | O4: =VLOOKUP(H4,'RM Used'!A:E,5,0) -> Count | P4: =VLOOKUP(H4,'RM Used'!A:F,6,0) -> 0.28 | Q4: =P4*N4 -> 0.28 | R4: =IFERROR(IF(B4="Reynolds",VLOOKUP(H4,'Yield & Time'!A:U,21,0),VLOOKUP(H4,'Yield & Time'!A:L,12,0)),0) -> 0 | S4: =R4*J4*E4*AO$1 -> 0 | T4: =(R4*Z4*J4*E4)/60 -> 0 | U4: =IF(A3=A4,0,VLOOKUP(A4,'Packing Time'!A:F,6,0)) -> 0 | V4: =U4*AO$1 -> 0 | W4: =(U4*Z4)/60 -> 0 | X4: =((R4*J4*E4)+U4)*AO$1*AP4 -> 0 | Y4: =X4*Z4 -> 0 | Z4: 1 | AA4: =Z4*N4 -> 1 | AB4: =AA4*P4 -> 0.28 | AC4: =(((R4*J4*E4)+U4)/60)*Z4*AP4 -> 0 | AD4: =AC4*60*AO$1 -> 0 | AF4: =IFERROR(VLOOKUP(AE4,'Chemical Cost'!A:D,4,0),0) -> 0 | AG4: =AF4*N4/3 -> 0 | AH4: =AF4*AA4/3 -> 0 | AI4: =IFERROR((Q4*Z4)+(Z4*X4)+AH4,0) -> 0.28 | AJ4: =IFERROR(VLOOKUP(A4,'All Products'!A:F,6,0),0) -> 1.67 | AL4: 0.85 | AM4: 0.15 | AN4: #N/A | AP4: 1.1 | AQ4: =(((R4*J4*E4)+U4)/60)*AP4 -> 0 | AR4: =_xlfn.XLOOKUP(F4,'RM Cost'!A:A,'RM Cost'!S:S) -> 0 | AS4: =_xlfn.XLOOKUP(A4,[3]Sheet1!$B:$B,[3]Sheet1!$B:$B) -> 1145CS | AT4: =_xlfn.XLOOKUP(H4,'Yield & Time'!A:A,'Yield & Time'!F:F) -> #N/A
A5: 1480CS | B5: Reynolds | C5: PREP ROOT VEG MIX CHNKY 2.5KG | D5: KG | E5: 2.5 | F5: =VLOOKUP(H5,'RM Used'!A:B,2,0) -> 032ACS | G5: =IFERROR(VLOOKUP(F5,'RM Cost'!A:B,2,0),"") -> RM - LRG PROCESSING CARROT X 1000KG | H5: Carrot - Peeled & Diced 25mm | I5: =VLOOKUP(F5,'RM Used'!B:D,3,0) -> RM-FOOD | J5: 0.25 | K5: =IF(I5="RM-FOOD",J5*E5,"") -> 0.625 | L5: =IFERROR(K5*Z5,0) -> 0.625 | M5: {=_xlfn.IFS(BOM!I5="RM-PACKING","100%",B5="Reynolds",VLOOKUP(H5,'Yield & Time'!A:V,22,0),BOM!B5="Dnata",VLOOKUP(BOM!H5,'Yield & Time'!A:M,13,0),B5="NK",VLOOKUP(H5,'Yield & Time'!A:X,24,0))} -> 0.71506674 | N5: =IFERROR(IF(I5="RM-FOOD",(E5*J5)/M5,1),0) -> 0.87404429 | O5: =VLOOKUP(H5,'RM Used'!A:E,5,0) -> KG | P5: =VLOOKUP(H5,'RM Used'!A:F,6,0) -> 0.38 | Q5: =P5*N5 -> 0.33213683 | R5: =IFERROR(IF(B5="Reynolds",VLOOKUP(H5,'Yield & Time'!A:U,21,0),VLOOKUP(H5,'Yield & Time'!A:L,12,0)),0) -> 1.2475449 | S5: =R5*J5*E5*AO$1 -> 0.26393372 | T5: =(R5*Z5*J5*E5)/60 -> 0.01299526 | U5: =IF(A4=A5,0,VLOOKUP(A5,'Packing Time'!A:F,6,0)) -> 0.875 | V5: =U5*AO$1 -> 0.2961875 | W5: =(U5*Z5)/60 -> 0.014583333 | X5: =((R5*J5*E5)+U5)*AO$1*AP5 -> 0.61613334 | Y5: =X5*Z5 -> 0.61613334 | Z5: 1 | AA5: =Z5*N5 -> 0.87404429 | AB5: =AA5*P5 -> 0.33213683 | AC5: =(((R5*J5*E5)+U5)/60)*Z5*AP5 -> 0.030336452 | AD5: =AC5*60*AO$1 -> 0.61613334 | AF5: =IFERROR(VLOOKUP(AE5,'Chemical Cost'!A:D,4,0),0) -> 0 | AG5: =AF5*N5/3 -> 0 | AH5: =AF5*AA5/3 -> 0 | AI5: =IFERROR((Q5*Z5)+(Z5*X5)+AH5,0) -> 0.94827018 | AJ5: =IFERROR(VLOOKUP(A5,'All Products'!A:F,6,0),0) -> 6.19 | AK5: =AJ5*Z5*J5 -> 1.5475 | AL5: 1 | AN5: #N/A | AP5: 1.1 | AQ5: =(((R5*J5*E5)+U5)/60)*AP5 -> 0.030336452 | AR5: =_xlfn.XLOOKUP(F5,'RM Cost'!A:A,'RM Cost'!S:S) -> 0 | AS5: =_xlfn.XLOOKUP(A5,[3]Sheet1!$B:$B,[3]Sheet1!$B:$B) -> 1480CS | AT5: =_xlfn.XLOOKUP(H5,'Yield & Time'!A:A,'Yield & Time'!F:F) -> 0
A6: 1480CS | B6: Reynolds | C6: PREP ROOT VEG MIX CHNKY 2.5KG | D6: KG | E6: 2.5 | F6: =VLOOKUP(H6,'RM Used'!A:B,2,0) -> 3277CS | G6: =IFERROR(VLOOKUP(F6,'RM Cost'!A:B,2,0),"") -> RM - SWEDE 12.5KG | H6: Swede - Diced 25MM | I6: =VLOOKUP(F6,'RM Used'!B:D,3,0) -> RM-FOOD | J6: 0.25 | K6: =IF(I6="RM-FOOD",J6*E6,"") -> 0.625 | L6: =IFERROR(K6*Z6,0) -> 0.625 | M6: {=_xlfn.IFS(BOM!I6="RM-PACKING","100%",B6="Reynolds",VLOOKUP(H6,'Yield & Time'!A:V,22,0),BOM!B6="Dnata",VLOOKUP(BOM!H6,'Yield & Time'!A:M,13,0),B6="NK",VLOOKUP(H6,'Yield & Time'!A:X,24,0))} -> 0.82357724 | N6: =IFERROR(IF(I6="RM-FOOD",(E6*J6)/M6,1),0) -> 0.7588845 | O6: =VLOOKUP(H6,'RM Used'!A:E,5,0) -> KG | P6: =VLOOKUP(H6,'RM Used'!A:F,6,0) -> 0.52 | Q6: =P6*N6 -> 0.39461994 | R6: =IFERROR(IF(B6="Reynolds",VLOOKUP(H6,'Yield & Time'!A:U,21,0),VLOOKUP(H6,'Yield & Time'!A:L,12,0)),0) -> 1.9442895 | S6: =R6*J6*E6*AO$1 -> 0.41133874 | T6: =(R6*Z6*J6*E6)/60 -> 0.020253015 | U6: =IF(A5=A6,0,VLOOKUP(A6,'Packing Time'!A:F,6,0)) -> 0 | V6: =U6*AO$1 -> 0 | W6: =(U6*Z6)/60 -> 0 | X6: =((R6*J6*E6)+U6)*AO$1*AP6 -> 0.45247261 | Y6: =X6*Z6 -> 0.45247261 | Z6: 1 | AA6: =Z6*N6 -> 0.7588845 | AB6: =AA6*P6 -> 0.39461994 | AC6: =(((R6*J6*E6)+U6)/60)*Z6*AP6 -> 0.022278317 | AD6: =AC6*60*AO$1 -> 0.45247261 | AF6: =IFERROR(VLOOKUP(AE6,'Chemical Cost'!A:D,4,0),0) -> 0 | AG6: =AF6*N6/3 -> 0 | AH6: =AF6*AA6/3 -> 0 | AI6: =IFERROR((Q6*Z6)+(Z6*X6)+AH6,0) -> 0.84709255 | AJ6: =IFERROR(VLOOKUP(A6,'All Products'!A:F,6,0),0) -> 6.19 | AK6: =AJ6*Z6*J6 -> 1.5475 | AL6: 1 | AN6: #N/A | AP6: 1.1 | AQ6: =(((R6*J6*E6)+U6)/60)*AP6 -> 0.022278317 | AR6: =_xlfn.XLOOKUP(F6,'RM Cost'!A:A,'RM Cost'!S:S) -> 0 | AS6: =_xlfn.XLOOKUP(A6,[3]Sheet1!$B:$B,[3]Sheet1!$B:$B) -> 1480CS | AT6: =_xlfn.XLOOKUP(H6,'Yield & Time'!A:A,'Yield & Time'!F:F) -> 0
A7: 1480CS | B7: Reynolds | C7: PREP ROOT VEG MIX CHNKY 2.5KG | D7: KG | E7: 2.5 | F7: =VLOOKUP(H7,'RM Used'!A:B,2,0) -> 3342CS | G7: =IFERROR(VLOOKUP(F7,'RM Cost'!A:B,2,0),"") -> RM - ORI MOOLI X 15 EA | H7: Mooli - Diced 25mm | I7: =VLOOKUP(F7,'RM Used'!B:D,3,0) -> RM-FOOD | J7: 0.25 | K7: =IF(I7="RM-FOOD",J7*E7,"") -> 0.625 | L7: =IFERROR(K7*Z7,0) -> 0.625 | M7: {=_xlfn.IFS(BOM!I7="RM-PACKING","100%",B7="Reynolds",VLOOKUP(H7,'Yield & Time'!A:V,22,0),BOM!B7="Dnata",VLOOKUP(BOM!H7,'Yield & Time'!A:M,13,0),B7="NK",VLOOKUP(H7,'Yield & Time'!A:X,24,0))} -> 0.82 | N7: =IFERROR(IF(I7="RM-FOOD",(E7*J7)/M7,1),0) -> 0.76219512 | O7: =VLOOKUP(H7,'RM Used'!A:E,5,0) -> KG | P7: =VLOOKUP(H7,'RM Used'!A:F,6,0) -> 1.23 | Q7: =P7*N7 -> 0.9375 | R7: =IFERROR(IF(B7="Reynolds",VLOOKUP(H7,'Yield & Time'!A:U,21,0),VLOOKUP(H7,'Yield & Time'!A:L,12,0)),0) -> 1.351626 | S7: =R7*J7*E7*AO$1 -> 0.28595338 | T7: =(R7*Z7*J7*E7)/60 -> 0.014079438 | U7: =IF(A6=A7,0,VLOOKUP(A7,'Packing Time'!A:F,6,0)) -> 0 | V7: =U7*AO$1 -> 0 | W7: =(U7*Z7)/60 -> 0 | X7: =((R7*J7*E7)+U7)*AO$1*AP7 -> 0.31454872 | Y7: =X7*Z7 -> 0.31454872 | Z7: 1 | AA7: =Z7*N7 -> 0.76219512 | AB7: =AA7*P7 -> 0.9375 | AC7: =(((R7*J7*E7)+U7)/60)*Z7*AP7 -> 0.015487381 | AD7: =AC7*60*AO$1 -> 0.31454872 | AF7: =IFERROR(VLOOKUP(AE7,'Chemical Cost'!A:D,4,0),0) -> 0 | AG7: =AF7*N7/3 -> 0 | AH7: =AF7*AA7/3 -> 0 | AI7: =IFERROR((Q7*Z7)+(Z7*X7)+AH7,0) -> 1.2520487 | AJ7: =IFERROR(VLOOKUP(A7,'All Products'!A:F,6,0),0) -> 6.19 | AK7: =AJ7*Z7*J7 -> 1.5475 | AL7: 1 | AN7: #N/A | AP7: 1.1 | AQ7: =(((R7*J7*E7)+U7)/60)*AP7 -> 0.015487381 | AR7: =_xlfn.XLOOKUP(F7,'RM Cost'!A:A,'RM Cost'!S:S) -> 0 | AS7: =_xlfn.XLOOKUP(A7,[3]Sheet1!$B:$B,[3]Sheet1!$B:$B) -> 1480CS | AT7: =_xlfn.XLOOKUP(H7,'Yield & Time'!A:A,'Yield & Time'!F:F) -> 0
A8: 1480CS | B8: Reynolds | C8: PREP ROOT VEG MIX CHNKY 2.5KG | D8: KG | E8: 2.5 | F8: =VLOOKUP(H8,'RM Used'!A:B,2,0) -> 3191CS | G8: =IFERROR(VLOOKUP(F8,'RM Cost'!A:B,2,0),"") -> RM - PARSNIPS 10KG | H8: Parsnip - Diced 25mm MC | I8: =VLOOKUP(F8,'RM Used'!B:D,3,0) -> RM-FOOD | J8: 0.25 | K8: =IF(I8="RM-FOOD",J8*E8,"") -> 0.625 | L8: =IFERROR(K8*Z8,0) -> 0.625 | M8: {=_xlfn.IFS(BOM!I8="RM-PACKING","100%",B8="Reynolds",VLOOKUP(H8,'Yield & Time'!A:V,22,0),BOM!B8="Dnata",VLOOKUP(BOM!H8,'Yield & Time'!A:M,13,0),B8="NK",VLOOKUP(H8,'Yield & Time'!A:X,24,0))} -> 0.66601942 | N8: =IFERROR(IF(I8="RM-FOOD",(E8*J8)/M8,1),0) -> 0.93841108 | O8: =VLOOKUP(H8,'RM Used'!A:E,5,0) -> KG | P8: =VLOOKUP(H8,'RM Used'!A:F,6,0) -> 0.76 | Q8: =P8*N8 -> 0.71319242 | R8: =IFERROR(IF(B8="Reynolds",VLOOKUP(H8,'Yield & Time'!A:U,21,0),VLOOKUP(H8,'Yield & Time'!A:L,12,0)),0) -> 2.9061224 | S8: =R8*J8*E8*AO$1 -> 0.61482653 | T8: =(R8*Z8*J8*E8)/60 -> 0.030272109 | U8: =IF(A7=A8,0,VLOOKUP(A8,'Packing Time'!A:F,6,0)) -> 0 | V8: =U8*AO$1 -> 0 | W8: =(U8*Z8)/60 -> 0 | X8: =((R8*J8*E8)+U8)*AO$1*AP8 -> 0.67630918 | Y8: =X8*Z8 -> 0.67630918 | Z8: 1 | AA8: =Z8*N8 -> 0.93841108 | AB8: =AA8*P8 -> 0.71319242 | AC8: =(((R8*J8*E8)+U8)/60)*Z8*AP8 -> 0.03329932 | AD8: =AC8*60*AO$1 -> 0.67630918 | AE8: =VLOOKUP(H8,'Yield & Time'!A:R,18,0) -> SODIUM METABISULPHITE | AF8: =IFERROR(VLOOKUP(AE8,'Chemical Cost'!A:D,4,0),0) -> 0.0097586225 | AG8: =AF8*N8/3 -> 0.0030525332 | AH8: =AF8*AA8/3 -> 0.0030525332 | AI8: =IFERROR((Q8*Z8)+(Z8*X8)+AH8,0) -> 1.3925541 | AJ8: =IFERROR(VLOOKUP(A8,'All Products'!A:F,6,0),0) -> 6.19 | AK8: =AJ8*Z8*J8 -> 1.5475 | AL8: 1 | AN8: #N/A | AP8: 1.1 | AQ8: =(((R8*J8*E8)+U8)/60)*AP8 -> 0.03329932 | AR8: =_xlfn.XLOOKUP(F8,'RM Cost'!A:A,'RM Cost'!S:S) -> 0 | AS8: =_xlfn.XLOOKUP(A8,[3]Sheet1!$B:$B,[3]Sheet1!$B:$B) -> 1480CS | AT8: =_xlfn.XLOOKUP(H8,'Yield & Time'!A:A,'Yield & Time'!F:F) -> 0
A9: 1480CS | B9: Reynolds | C9: PREP ROOT VEG MIX CHNKY 2.5KG | D9: KG | E9: 2.5 | F9: =VLOOKUP(H9,'RM Used'!A:B,2,0) -> P0020 | G9: =IFERROR(VLOOKUP(F9,'RM Cost'!A:B,2,0),"") -> PALE BLUE BAG 430X430MM | H9: BLUE TINT BAGS ON A ROLL - SMALL | I9: =VLOOKUP(F9,'RM Used'!B:D,3,0) -> RM-PACKING | J9: 1 | K9: =IF(I9="RM-FOOD",J9*E9,"") | L9: =IFERROR(K9*Z9,0) -> 0 | M9: {=_xlfn.IFS(BOM!I9="RM-PACKING","100%",B9="Reynolds",VLOOKUP(H9,'Yield & Time'!A:V,22,0),BOM!B9="Dnata",VLOOKUP(BOM!H9,'Yield & Time'!A:M,13,0),B9="NK",VLOOKUP(H9,'Yield & Time'!A:X,24,0))} -> 100% | N9: =IFERROR(IF(I9="RM-FOOD",(E9*J9)/M9,1),0) -> 1 | O9: =VLOOKUP(H9,'RM Used'!A:E,5,0) -> Count | P9: =VLOOKUP(H9,'RM Used'!A:F,6,0) -> 0.09 | Q9: =P9*N9 -> 0.09 | R9: =IFERROR(IF(B9="Reynolds",VLOOKUP(H9,'Yield & Time'!A:U,21,0),VLOOKUP(H9,'Yield & Time'!A:L,12,0)),0) -> 0 | S9: =R9*J9*E9*AO$1 -> 0 | T9: =(R9*Z9*J9*E9)/60 -> 0 | U9: =IF(A8=A9,0,VLOOKUP(A9,'Packing Time'!A:F,6,0)) -> 0 | V9: =U9*AO$1 -> 0 | W9: =(U9*Z9)/60 -> 0 | X9: =((R9*J9*E9)+U9)*AO$1*AP9 -> 0 | Y9: =X9*Z9 -> 0 | Z9: 1 | AA9: =Z9*N9 -> 1 | AB9: =AA9*P9 -> 0.09 | AC9: =(((R9*J9*E9)+U9)/60)*Z9*AP9 -> 0 | AD9: =AC9*60*AO$1 -> 0 | AF9: =IFERROR(VLOOKUP(AE9,'Chemical Cost'!A:D,4,0),0) -> 0 | AG9: =AF9*N9/3 -> 0 | AH9: =AF9*AA9/3 -> 0 | AI9: =IFERROR((Q9*Z9)+(Z9*X9)+AH9,0) -> 0.09 | AJ9: =IFERROR(VLOOKUP(A9,'All Products'!A:F,6,0),0) -> 6.19 | AL9: 1 | AN9: #N/A | AP9: 1.1 | AQ9: =(((R9*J9*E9)+U9)/60)*AP9 -> 0 | AR9: =_xlfn.XLOOKUP(F9,'RM Cost'!A:A,'RM Cost'!S:S) -> 0 | AS9: =_xlfn.XLOOKUP(A9,[3]Sheet1!$B:$B,[3]Sheet1!$B:$B) -> 1480CS | AT9: =_xlfn.XLOOKUP(H9,'Yield & Time'!A:A,'Yield & Time'!F:F) -> #N/A
A10: 1480CS | B10: Reynolds | C10: PREP ROOT VEG MIX CHNKY 2.5KG | D10: KG | E10: 2.5 | F10: =VLOOKUP(H10,'RM Used'!A:B,2,0) -> P0016 | G10: =IFERROR(VLOOKUP(F10,'RM Cost'!A:B,2,0),"") -> REY 40 30 BOX | H10: black box | I10: =VLOOKUP(F10,'RM Used'!B:D,3,0) -> RM-PACKING | J10: 1 | K10: =IF(I10="RM-FOOD",J10*E10,"") | L10: =IFERROR(K10*Z10,0) -> 0 | M10: {=_xlfn.IFS(BOM!I10="RM-PACKING","100%",B10="Reynolds",VLOOKUP(H10,'Yield & Time'!A:V,22,0),BOM!B10="Dnata",VLOOKUP(BOM!H10,'Yield & Time'!A:M,13,0),B10="NK",VLOOKUP(H10,'Yield & Time'!A:X,24,0))} -> 100% | N10: =IFERROR(IF(I10="RM-FOOD",(E10*J10)/M10,1),0) -> 1 | O10: =VLOOKUP(H10,'RM Used'!A:E,5,0) -> Count | P10: =VLOOKUP(H10,'RM Used'!A:F,6,0) -> 0.28 | Q10: =P10*N10 -> 0.28 | R10: =IFERROR(IF(B10="Reynolds",VLOOKUP(H10,'Yield & Time'!A:U,21,0),VLOOKUP(H10,'Yield & Time'!A:L,12,0)),0) -> 0 | S10: =R10*J10*E10*AO$1 -> 0 | T10: =(R10*Z10*J10*E10)/60 -> 0 | U10: =IF(A9=A10,0,VLOOKUP(A10,'Packing Time'!A:F,6,0)) -> 0 | V10: =U10*AO$1 -> 0 | W10: =(U10*Z10)/60 -> 0 | X10: =((R10*J10*E10)+U10)*AO$1*AP10 -> 0 | Y10: =X10*Z10 -> 0 | Z10: 1 | AA10: =Z10*N10 -> 1 | AB10: =AA10*P10 -> 0.28 | AC10: =(((R10*J10*E10)+U10)/60)*Z10*AP10 -> 0 | AD10: =AC10*60*AO$1 -> 0 | AF10: =IFERROR(VLOOKUP(AE10,'Chemical Cost'!A:D,4,0),0) -> 0 | AG10: =AF10*N10/3 -> 0 | AH10: =AF10*AA10/3 -> 0 | AI10: =IFERROR((Q10*Z10)+(Z10*X10)+AH10,0) -> 0.28 | AJ10: =IFERROR(VLOOKUP(A10,'All Products'!A:F,6,0),0) -> 6.19 | AL10: 1 | AN10: #N/A | AP10: 1.1 | AQ10: =(((R10*J10*E10)+U10)/60)*AP10 -> 0 | AR10: =_xlfn.XLOOKUP(F10,'RM Cost'!A:A,'RM Cost'!S:S) -> 0 | AS10: =_xlfn.XLOOKUP(A10,[3]Sheet1!$B:$B,[3]Sheet1!$B:$B) -> 1480CS | AT10: =_xlfn.XLOOKUP(H10,'Yield & Time'!A:A,'Yield & Time'!F:F) -> #N/A
A11: 765ACS | B11: Reynolds | C11: COLESLAW MIX 8x500G | D11: KG | E11: 4 | F11: =VLOOKUP(H11,'RM Used'!A:B,2,0) -> 032ACS | G11: =IFERROR(VLOOKUP(F11,'RM Cost'!A:B,2,0),"") -> RM - LRG PROCESSING CARROT X 1000KG | H11: Carrot - Julienne | I11: =VLOOKUP(F11,'RM Used'!B:D,3,0) -> RM-FOOD | J11: 0.5 | K11: =IF(I11="RM-FOOD",J11*E11,"") -> 2 | L11: =IFERROR(K11*Z11,0) -> 2 | M11: {=_xlfn.IFS(BOM!I11="RM-PACKING","100%",B11="Reynolds",VLOOKUP(H11,'Yield & Time'!A:V,22,0),BOM!B11="Dnata",VLOOKUP(BOM!H11,'Yield & Time'!A:M,13,0),B11="NK",VLOOKUP(H11,'Yield & Time'!A:X,24,0))} -> 0.7533 | N11: =IFERROR(IF(I11="RM-FOOD",(E11*J11)/M11,1),0) -> 2.6549847 | O11: =VLOOKUP(H11,'RM Used'!A:E,5,0) -> KG | P11: =VLOOKUP(H11,'RM Used'!A:F,6,0) -> 0.38 | Q11: =P11*N11 -> 1.0088942 | R11: =IFERROR(IF(B11="Reynolds",VLOOKUP(H11,'Yield & Time'!A:U,21,0),VLOOKUP(H11,'Yield & Time'!A:L,12,0)),0) -> 0.90531915 | S11: =R11*J11*E11*AO$1 -> 0.61290106 | T11: =(R11*Z11*J11*E11)/60 -> 0.030177305 | U11: =IF(A10=A11,0,VLOOKUP(A11,'Packing Time'!A:F,6,0)) -> 2.3 | V11: =U11*AO$1 -> 0.77855 | W11: =(U11*Z11)/60 -> 0.038333333 | X11: =((R11*J11*E11)+U11)*AO$1*AP11 -> 1.5305962 | Y11: =X11*Z11 -> 1.5305962 | Z11: 1 | AA11: =Z11*N11 -> 2.6549847 | AB11: =AA11*P11 -> 1.0088942 | AC11: =(((R11*J11*E11)+U11)/60)*Z11*AP11 -> 0.075361702 | AD11: =AC11*60*AO$1 -> 1.5305962 | AE11: =VLOOKUP(H11,'Yield & Time'!A:R,18,0) -> CHLORINE | AF11: =IFERROR(VLOOKUP(AE11,'Chemical Cost'!A:D,4,0),0) -> 0.027756518 | AG11: =AF11*N11/3 -> 0.024564377 | AH11: =AF11*AA11/3 -> 0.024564377 | AI11: =IFERROR((Q11*Z11)+(Z11*X11)+AH11,0) -> 2.5640547 | AJ11: =IFERROR(VLOOKUP(A11,'All Products'!A:F,6,0),0) -> 10.32 | AK11: =AJ11*Z11*J11 -> 5.16 | AL11: 0.85 | AM11: 0.15 | AN11: #N/A | AP11: 1.1 | AQ11: =(((R11*J11*E11)+U11)/60)*AP11 -> 0.075361702 | AR11: =_xlfn.XLOOKUP(F11,'RM Cost'!A:A,'RM Cost'!S:S) -> 0 | AS11: =_xlfn.XLOOKUP(A11,[3]Sheet1!$B:$B,[3]Sheet1!$B:$B) -> 765ACS | AT11: =_xlfn.XLOOKUP(H11,'Yield & Time'!A:A,'Yield & Time'!O:O) -> Yes
A12: 765ACS | B12: Reynolds | C12: COLESLAW MIX 8x500G | D12: KG | E12: 4 | F12: =VLOOKUP(H12,'RM Used'!A:B,2,0) -> S3998CS | G12: =IFERROR(VLOOKUP(F12,'RM Cost'!A:B,2,0),"") -> RM - DECORED RED CABBAGE 1/3 1200KG | H12: CABB RED SHR 3MM M/C RTE | I12: =VLOOKUP(F12,'RM Used'!B:D,3,0) -> RM-FOOD | J12: 0.5 | K12: =IF(I12="RM-FOOD",J12*E12,"") -> 2 | L12: =IFERROR(K12*Z12,0) -> 2 | M12: {=_xlfn.IFS(BOM!I12="RM-PACKING","100%",B12="Reynolds",VLOOKUP(H12,'Yield & Time'!A:V,22,0),BOM!B12="Dnata",VLOOKUP(BOM!H12,'Yield & Time'!A:M,13,0),B12="NK",VLOOKUP(H12,'Yield & Time'!A:X,24,0))} -> 0.7513804 | N12: =IFERROR(IF(I12="RM-FOOD",(E12*J12)/M12,1),0) -> 2.6617676 | O12: =VLOOKUP(H12,'RM Used'!A:E,5,0) -> KG | P12: =VLOOKUP(H12,'RM Used'!A:F,6,0) -> 0.38 | Q12: =P12*N12 -> 1.0114717 | R12: =IFERROR(IF(B12="Reynolds",VLOOKUP(H12,'Yield & Time'!A:U,21,0),VLOOKUP(H12,'Yield & Time'!A:L,12,0)),0) -> 0.76261571 | S12: =R12*J12*E12*AO$1 -> 0.51629083 | T12: =(R12*Z12*J12*E12)/60 -> 0.025420524 | U12: =IF(A11=A12,0,VLOOKUP(A12,'Packing Time'!A:F,6,0)) -> 0 | V12: =U12*AO$1 -> 0 | W12: =(U12*Z12)/60 -> 0 | X12: =((R12*J12*E12)+U12)*AO$1*AP12 -> 0.56791992 | Y12: =X12*Z12 -> 0.56791992 | Z12: 1 | AA12: =Z12*N12 -> 2.6617676 | AB12: =AA12*P12 -> 1.0114717 | AC12: =(((R12*J12*E12)+U12)/60)*Z12*AP12 -> 0.027962576 | AD12: =AC12*60*AO$1 -> 0.56791992 | AE12: =VLOOKUP(H12,'Yield & Time'!A:R,18,0) -> CHLORINE | AF12: =IFERROR(VLOOKUP(AE12,'Chemical Cost'!A:D,4,0),0) -> 0.027756518 | AG12: =AF12*N12/3 -> 0.024627133 | AH12: =AF12*AA12/3 -> 0.024627133 | AI12: =IFERROR((Q12*Z12)+(Z12*X12)+AH12,0) -> 1.6040187 | AJ12: =IFERROR(VLOOKUP(A12,'All Products'!A:F,6,0),0) -> 10.32 | AK12: =AJ12*Z12*J12 -> 5.16 | AL12: 0.85 | AM12: 0.15 | AN12: #N/A | AP12: 1.1 | AQ12: =(((R12*J12*E12)+U12)/60)*AP12 -> 0.027962576 | AR12: =_xlfn.XLOOKUP(F12,'RM Cost'!A:A,'RM Cost'!S:S) -> 0.29914854 | AS12: =_xlfn.XLOOKUP(A12,[3]Sheet1!$B:$B,[3]Sheet1!$B:$B) -> 765ACS | AT12: =_xlfn.XLOOKUP(H12,'Yield & Time'!A:A,'Yield & Time'!O:O) -> Yes
A13: 765ACS | B13: Reynolds | C13: COLESLAW MIX 8x500G | D13: KG | E13: 4 | F13: =VLOOKUP(H13,'RM Used'!A:B,2,0) -> P0005 | G13: =IFERROR(VLOOKUP(F13,'RM Cost'!A:B,2,0),"") -> SOL 30EL # PPLUS 630x1000 BLUE -8 | H13: SOL 30EL # PPLUS 630x1000 BLUE -8 | I13: =VLOOKUP(F13,'RM Used'!B:D,3,0) -> RM-PACKING | J13: 1 | K13: =IF(I13="RM-FOOD",J13*E13,"") | L13: =IFERROR(K13*Z13,0) -> 0 | M13: {=_xlfn.IFS(BOM!I13="RM-PACKING","100%",B13="Reynolds",VLOOKUP(H13,'Yield & Time'!A:V,22,0),BOM!B13="Dnata",VLOOKUP(BOM!H13,'Yield & Time'!A:M,13,0),B13="NK",VLOOKUP(H13,'Yield & Time'!A:X,24,0))} -> 100% | N13: =IFERROR(IF(I13="RM-FOOD",(E13*J13)/M13,1),0) -> 1 | O13: =VLOOKUP(H13,'RM Used'!A:E,5,0) -> Count | P13: =VLOOKUP(H13,'RM Used'!A:F,6,0) -> 0.64 | Q13: =P13*N13 -> 0.64 | R13: =IFERROR(IF(B13="Reynolds",VLOOKUP(H13,'Yield & Time'!A:U,21,0),VLOOKUP(H13,'Yield & Time'!A:L,12,0)),0) -> 0 | S13: =R13*J13*E13*AO$1 -> 0 | T13: =(R13*Z13*J13*E13)/60 -> 0 | U13: =IF(A12=A13,0,VLOOKUP(A13,'Packing Time'!A:F,6,0)) -> 0 | V13: =U13*AO$1 -> 0 | W13: =(U13*Z13)/60 -> 0 | X13: =((R13*J13*E13)+U13)*AO$1*AP13 -> 0 | Y13: =X13*Z13 -> 0 | Z13: 1 | AA13: =Z13*N13 -> 1 | AB13: =AA13*P13 -> 0.64 | AC13: =(((R13*J13*E13)+U13)/60)*Z13*AP13 -> 0 | AD13: =AC13*60*AO$1 -> 0 | AF13: =IFERROR(VLOOKUP(AE13,'Chemical Cost'!A:D,4,0),0) -> 0 | AG13: =AF13*N13/3 -> 0 | AH13: =AF13*AA13/3 -> 0 | AI13: =IFERROR((Q13*Z13)+(Z13*X13)+AH13,0) -> 0.64 | AJ13: =IFERROR(VLOOKUP(A13,'All Products'!A:F,6,0),0) -> 10.32 | AL13: 0.85 | AM13: 0.15 | AN13: #N/A | AP13: 1.1 | AQ13: =(((R13*J13*E13)+U13)/60)*AP13 -> 0 | AR13: =_xlfn.XLOOKUP(F13,'RM Cost'!A:A,'RM Cost'!S:S) -> 0 | AS13: =_xlfn.XLOOKUP(A13,[3]Sheet1!$B:$B,[3]Sheet1!$B:$B) -> 765ACS | AT13: =_xlfn.XLOOKUP(H13,'Yield & Time'!A:A,'Yield & Time'!F:F) -> #N/A
A14: 765ACS | B14: Reynolds | C14: COLESLAW MIX 8x500G | D14: KG | E14: 4 | F14: =VLOOKUP(H14,'RM Used'!A:B,2,0) -> P0016 | G14: =IFERROR(VLOOKUP(F14,'RM Cost'!A:B,2,0),"") -> REY 40 30 BOX | H14: black box | I14: =VLOOKUP(F14,'RM Used'!B:D,3,0) -> RM-PACKING | J14: 1 | K14: =IF(I14="RM-FOOD",J14*E14,"") | L14: =IFERROR(K14*Z14,0) -> 0 | M14: {=_xlfn.IFS(BOM!I14="RM-PACKING","100%",B14="Reynolds",VLOOKUP(H14,'Yield & Time'!A:V,22,0),BOM!B14="Dnata",VLOOKUP(BOM!H14,'Yield & Time'!A:M,13,0),B14="NK",VLOOKUP(H14,'Yield & Time'!A:X,24,0))} -> 100% | N14: =IFERROR(IF(I14="RM-FOOD",(E14*J14)/M14,1),0) -> 1 | O14: =VLOOKUP(H14,'RM Used'!A:E,5,0) -> Count | P14: =VLOOKUP(H14,'RM Used'!A:F,6,0) -> 0.28 | Q14: =P14*N14 -> 0.28 | R14: =IFERROR(IF(B14="Reynolds",VLOOKUP(H14,'Yield & Time'!A:U,21,0),VLOOKUP(H14,'Yield & Time'!A:L,12,0)),0) -> 0 | S14: =R14*J14*E14*AO$1 -> 0 | T14: =(R14*Z14*J14*E14)/60 -> 0 | U14: =IF(A13=A14,0,VLOOKUP(A14,'Packing Time'!A:F,6,0)) -> 0 | V14: =U14*AO$1 -> 0 | W14: =(U14*Z14)/60 -> 0 | X14: =((R14*J14*E14)+U14)*AO$1*AP14 -> 0 | Y14: =X14*Z14 -> 0 | Z14: 1 | AA14: =Z14*N14 -> 1 | AB14: =AA14*P14 -> 0.28 | AC14: =(((R14*J14*E14)+U14)/60)*Z14*AP14 -> 0 | AD14: =AC14*60*AO$1 -> 0 | AF14: =IFERROR(VLOOKUP(AE14,'Chemical Cost'!A:D,4,0),0) -> 0 | AG14: =AF14*N14/3 -> 0 | AH14: =AF14*AA14/3 -> 0 | AI14: =IFERROR((Q14*Z14)+(Z14*X14)+AH14,0) -> 0.28 | AJ14: =IFERROR(VLOOKUP(A14,'All Products'!A:F,6,0),0) -> 10.32 | AL14: 0.85 | AM14: 0.15 | AN14: #N/A | AP14: 1.1 | AQ14: =(((R14*J14*E14)+U14)/60)*AP14 -> 0 | AR14: =_xlfn.XLOOKUP(F14,'RM Cost'!A:A,'RM Cost'!S:S) -> 0 | AS14: =_xlfn.XLOOKUP(A14,[3]Sheet1!$B:$B,[3]Sheet1!$B:$B) -> 765ACS | AT14: =_xlfn.XLOOKUP(H14,'Yield & Time'!A:A,'Yield & Time'!F:F) -> #N/A
A15: 1254CS | B15: Reynolds | C15: COLESLAW DRY MIX 1KG | D15: KG | E15: 1 | F15: =VLOOKUP(H15,'RM Used'!A:B,2,0) -> S3997CS | G15: =IFERROR(VLOOKUP(F15,'RM Cost'!A:B,2,0),"") -> RM - DECORE WHITE CABBAGE 1/3 1200KG | H15: Cabbage White - Sliced | I15: =VLOOKUP(F15,'RM Used'!B:D,3,0) -> RM-FOOD | J15: 0.7 | K15: =IF(I15="RM-FOOD",J15*E15,"") -> 0.7 | L15: =IFERROR(K15*Z15,0) -> 0.7 | M15: {=_xlfn.IFS(BOM!I15="RM-PACKING","100%",B15="Reynolds",VLOOKUP(H15,'Yield & Time'!A:V,22,0),BOM!B15="Dnata",VLOOKUP(BOM!H15,'Yield & Time'!A:M,13,0),B15="NK",VLOOKUP(H15,'Yield & Time'!A:X,24,0))} -> 0.77222322 | N15: =IFERROR(IF(I15="RM-FOOD",(E15*J15)/M15,1),0) -> 0.90647365 | O15: =VLOOKUP(H15,'RM Used'!A:E,5,0) -> KG | P15: =VLOOKUP(H15,'RM Used'!A:F,6,0) -> 0.34 | Q15: =P15*N15 -> 0.30820104 | R15: =IFERROR(IF(B15="Reynolds",VLOOKUP(H15,'Yield & Time'!A:U,21,0),VLOOKUP(H15,'Yield & Time'!A:L,12,0)),0) -> 0.82773481 | S15: =R15*J15*E15*AO$1 -> 0.19613176 | T15: =(R15*Z15*J15*E15)/60 -> 0.0096569061 | U15: =IF(A14=A15,0,VLOOKUP(A15,'Packing Time'!A:F,6,0)) -> 0.55 | V15: =U15*AO$1 -> 0.186175 | W15: =(U15*Z15)/60 -> 0.0091666667 | X15: =((R15*J15*E15)+U15)*AO$1*AP15 -> 0.42053744 | Y15: =X15*Z15 -> 0.42053744 | Z15: 1 | AA15: =Z15*N15 -> 0.90647365 | AB15: =AA15*P15 -> 0.30820104 | AC15: =(((R15*J15*E15)+U15)/60)*Z15*AP15 -> 0.02070593 | AD15: =AC15*60*AO$1 -> 0.42053744 | AE15: =VLOOKUP(H15,'Yield & Time'!A:R,18,0) -> CHLORINE | AF15: =IFERROR(VLOOKUP(AE15,'Chemical Cost'!A:D,4,0),0) -> 0.027756518 | AG15: =AF15*N15/3 -> 0.0083868507 | AH15: =AF15*AA15/3 -> 0.0083868507 | AI15: =IFERROR((Q15*Z15)+(Z15*X15)+AH15,0) -> 0.73712533 | AJ15: =IFERROR(VLOOKUP(A15,'All Products'!A:F,6,0),0) -> 1.91 | AK15: =AJ15*Z15*J15 -> 1.337 | AL15: 0.8 | AM15: 0.2 | AN15: #N/A | AP15: 1.1 | AQ15: =(((R15*J15*E15)+U15)/60)*AP15 -> 0.02070593 | AR15: =_xlfn.XLOOKUP(F15,'RM Cost'!A:A,'RM Cost'!S:S) -> 0.29914854 | AS15: =_xlfn.XLOOKUP(A15,[3]Sheet1!$B:$B,[3]Sheet1!$B:$B) -> 1254CS | AT15: =_xlfn.XLOOKUP(H15,'Yield & Time'!A:A,'Yield & Time'!O:O) -> Yes
A16: 1254CS | B16: Reynolds | C16: COLESLAW DRY MIX 1KG | D16: KG | E16: 1 | F16: =VLOOKUP(H16,'RM Used'!A:B,2,0) -> 032ACS | G16: =IFERROR(VLOOKUP(F16,'RM Cost'!A:B,2,0),"") -> RM - LRG PROCESSING CARROT X 1000KG | H16: Carrot - Julienne | I16: =VLOOKUP(F16,'RM Used'!B:D,3,0) -> RM-FOOD | J16: 0.3 | K16: =IF(I16="RM-FOOD",J16*E16,"") -> 0.3 | L16: =IFERROR(K16*Z16,0) -> 0.3 | M16: {=_xlfn.IFS(BOM!I16="RM-PACKING","100%",B16="Reynolds",VLOOKUP(H16,'Yield & Time'!A:V,22,0),BOM!B16="Dnata",VLOOKUP(BOM!H16,'Yield & Time'!A:M,13,0),B16="NK",VLOOKUP(H16,'Yield & Time'!A:X,24,0))} -> 0.7533 | N16: =IFERROR(IF(I16="RM-FOOD",(E16*J16)/M16,1),0) -> 0.39824771 | O16: =VLOOKUP(H16,'RM Used'!A:E,5,0) -> KG | P16: =VLOOKUP(H16,'RM Used'!A:F,6,0) -> 0.38 | Q16: =P16*N16 -> 0.15133413 | R16: =IFERROR(IF(B16="Reynolds",VLOOKUP(H16,'Yield & Time'!A:U,21,0),VLOOKUP(H16,'Yield & Time'!A:L,12,0)),0) -> 0.90531915 | S16: =R16*J16*E16*AO$1 -> 0.09193516 | T16: =(R16*Z16*J16*E16)/60 -> 0.0045265957 | U16: =IF(A15=A16,0,VLOOKUP(A16,'Packing Time'!A:F,6,0)) -> 0 | V16: =U16*AO$1 -> 0 | W16: =(U16*Z16)/60 -> 0 | X16: =((R16*J16*E16)+U16)*AO$1*AP16 -> 0.10112868 | Y16: =X16*Z16 -> 0.10112868 | Z16: 1 | AA16: =Z16*N16 -> 0.39824771 | AB16: =AA16*P16 -> 0.15133413 | AC16: =(((R16*J16*E16)+U16)/60)*Z16*AP16 -> 0.0049792553 | AD16: =AC16*60*AO$1 -> 0.10112868 | AE16: =VLOOKUP(H16,'Yield & Time'!A:R,18,0) -> CHLORINE | AF16: =IFERROR(VLOOKUP(AE16,'Chemical Cost'!A:D,4,0),0) -> 0.027756518 | AG16: =AF16*N16/3 -> 0.0036846566 | AH16: =AF16*AA16/3 -> 0.0036846566 | AI16: =IFERROR((Q16*Z16)+(Z16*X16)+AH16,0) -> 0.25614746 | AJ16: =IFERROR(VLOOKUP(A16,'All Products'!A:F,6,0),0) -> 1.91 | AK16: =AJ16*Z16*J16 -> 0.573 | AL16: 0.8 | AM16: 0.2 | AN16: #N/A | AP16: 1.1 | AQ16: =(((R16*J16*E16)+U16)/60)*AP16 -> 0.0049792553 | AR16: =_xlfn.XLOOKUP(F16,'RM Cost'!A:A,'RM Cost'!S:S) -> 0 | AS16: =_xlfn.XLOOKUP(A16,[3]Sheet1!$B:$B,[3]Sheet1!$B:$B) -> 1254CS | AT16: =_xlfn.XLOOKUP(H16,'Yield & Time'!A:A,'Yield & Time'!O:O) -> Yes
